Workbook

Sheet 使い方
A1: ラック搭載図（台帳版）の使い方
A3: ■ 直すのは「機器台帳」シートだけです
A4: 機器を足す: 空いている行に1行書きます。ラック・面・開始U・U数・機器名は必ず入れます。
A5: 機器を外す: その行を削除します（行ごと消してください。値だけ消すと点検に残ります）。
A6: 機器を移す: 「開始U」を書き換えます。図は自動で動きます。
A7: 2U以上の機器: 「U数」に2以上を入れます。行を増やす必要はありません。
A8: 前面と背面の両方から見える機器: 「面」を『両面』にします。両方の図に出ます。
A10: ■ 図形は使っていません
A11: 「搭載図」シートは数式で機器名を引いています。図のセルを直接書き換えないでください（次に誰かが台帳を直すと消えます）。
A12: 図形が無いので、Teams で同時に開いても壊れません。
A14: ■ 電力の書き方
A15: 電圧V・電流A・口数は数値で入れます。『100V』『1系統』のように単位を付けると計算できません。
... A34: 個人の OneDrive にコピーを置くと、そちらだけ古くなります。コピーは作らないでください。

Sheet 機器台帳
A1: ラック | B1: 面 | C1: 開始U | D1: U数 | E1: 終了U | F1: 機器名 | G1: 資産番号 | H1: システム | I1: 用途 | J1: 重量kg | K1: 電圧V | L1: 系統数 | M1: 回路1 | N1: 電流1A | O1: 口数1 | P1: 回路2 | Q1: 電流2A | R1: 口数2 | S1: 回路3 | T1: 電流3A | U1: 口数3 | V1: マウントキット | W1: 耐震ベルト | X1: 備考 | Y1: 回路数 | Z1: 消費電力W | AA1: 両系1A | AB1: 両系2A | AC1: 両系3A | AD1: 点検
A2: E24-S8-1 | B2: 両面 | C2: 39 | D2: 1 | E2: =IF(C2="","",C2+D2-1) | F2: Dell S4128T-1 | G2: H1902245 | H2: AdTech | I2: SW | J2: 4.5 | K2: 100 | L2: 2 | M2: 100V 20A （1） | N2: 0.5 | O2: 1 | P2: 100V 20A （2） | Q2: 0.5 | R2: 1 | V2: ○ | Y2: =COUNT(N2,Q2,T2) | Z2: =IF(OR(K2="",NOT(ISNUMBER(K2))),"",K2*SUM(N2,Q2,T2)) | AA2: =IF(OR(Y2=0,N2=""),"",N2/Y2) | AB2: =IF(OR(Y2=0,Q2=""),"",Q2/Y2) | AC2: =IF(OR(Y2=0,T2=""),"",T2/Y2) | AD2: =IF(F2="","",IF((IF(AND(Y2=0,NOT(SUMPRODUCT(--ISNUMBER(SEARCH({"棚板","棚","アングル","ｱﾝｸﾞﾙ","使用不可","ケーブル","ｹｰﾌﾞﾙ","PatchPnael","パッチ","引き出し","引出","ブランク","ﾌﾞﾗﾝｸ","マネージ","ﾏﾈｰｼﾞ","PDU","ONU"},$F2&"")))>0),NOT(SUMPRODUCT(--ISNUMBER(SEARCH({"電源オフ","未投入","停止","未使用","撤去"},$X2&"")))>0)),"／電力が未記入","")&IF(AND(NOT(ISNUMBER(J2)),NOT(SUMPRODUCT(--ISNUMBER(SEARCH({"棚板","棚","アングル","ｱﾝｸﾞﾙ","使用不可","ケーブル","ｹｰﾌﾞﾙ","PatchPnael","パッチ","引き出し","引出","ブランク","ﾌﾞﾗﾝｸ","マネージ","ﾏﾈｰｼﾞ","PDU","ONU"},$F2&"")))>0)),"／重量が未記入","")&IF(AND(K2<>"",NOT(ISNUMBER(K2))),"／電圧が数値でない","")&IF(AND(N2<>"",NOT(ISNUMBER(N2))),"／電流が数値でない","")&IF(AND(C2<>"",C2<1),"／開始Uが1未満","")&IF(AND(E2<>"",E2>IFERROR(VLOOKUP(A2,ラック定義!$A:$B,2,FALSE),47)),"／総Uをはみ出す","")&IF(AND(A2<>"",COUNTIF(ラック定義!$A:$A,A2)=0),"／ラックが定義にない","")&IF(AND(SUMPRODUCT((機器台帳!$A$2:$A$400=$A2)*((機器台帳!$B$2:$B$400=$B2)+(機器台帳!$B$2:$B$400="両面")+($B2="両面")>0)*(機器台帳!$C$2:$C$400<=$C2+$D2-1)*(機器台帳!$C$2:$C$400+機器台帳!$D$2:$D$400-1>=$C2)*(機器台帳!$F$2:$F$400<>""))-1>0,NOT(SUMPRODUCT(--ISNUMBER(SEARCH({"棚板","棚","アングル","ｱﾝｸﾞﾙ","使用不可","ケーブル","ｹｰﾌﾞﾙ","PatchPnael","パッチ","引き出し","引出","ブランク","ﾌﾞﾗﾝｸ","マネージ","ﾏﾈｰｼﾞ","PDU","ONU"},$F2&"")))>0)),"／同じUに他の機器(横並びなら正常)","")&IF(AND(M2<>"",COUNTIFS(回路定義!$A:$A,A2,回路定義!$B:$B,M2)=0),"／回路1が定義にない","")&IF(AND(P2<>"",COUNTIFS(回路定義!$A:$A,A2,回路定義!$B:$B,P2)=0),"／回路2が定義にない","")&IF(AND(S2<>"",COUNTIFS(回路定義!$A:$A,A2,回路定義!$B:$B,S2)=0),"／回路3が定義にない",""))="","",MID(IF(AND(Y2=0,NOT(SUMPRODUCT(--ISNUMBER(SEARCH({"棚板","棚","アングル","ｱﾝｸﾞﾙ","使用不可","ケーブル","ｹｰﾌﾞﾙ","PatchPnael","パッチ","引き出し","引出","ブランク","ﾌﾞﾗﾝｸ","マネージ","ﾏﾈｰｼﾞ","PDU","ONU"},$F2&"")))>0),NOT(SUMPRODUCT(--ISNUMBER(SEARCH({"電源オフ","未投入","停止","未使用","撤去"},$X2&"")))>0)),"／電力が未記入","")&IF(AND(NOT(ISNUMBER(J2)),NOT(SUMPRODUCT(--ISNUMBER(SEARCH({"棚板","棚","アングル","ｱﾝｸﾞﾙ","使用不可","ケーブル","ｹｰﾌﾞﾙ","PatchPnael","パッチ","引き出し","引出","ブランク","ﾌﾞﾗﾝｸ","マネージ","ﾏﾈｰｼﾞ","PDU","ONU"},$F2&"")))>0)),"／重量が未記入","")&IF(AND(K2<>"",NOT(ISNUMBER(K2))),"／電圧が数値でない","")&IF(AND(N2<>"",NOT(ISNUMBER(N2))),"／電流が数値でない","")&IF(AND(C2<>"",C2<1),"／開始Uが1未満","")&IF(AND(E2<>"",E2>IFERROR(VLOOKUP(A2,ラック定義!$A:$B,2,FALSE),47)),"／総Uをはみ出す","")&IF(AND(A2<>"",COUNTIF(ラック定義!$A:$A,A2)=0),"／ラックが定義にない","")&IF(AND(SUMPRODUCT((機器台帳!$A$2:$A$400=$A2)*((機器台帳!$B$2:$B$400=$B2)+(機器台帳!$B$2:$B$400="両面")+($B2="両面")>0)*(機器台帳!$C$2:$C$400<=$C2+$D2-1)*(機器台帳!$C$2:$C$400+機器台帳!$D$2:$D$400-1>=$C2)*(機器台帳!$F$2:$F$400<>""))-1>0,NOT(SUMPRODUCT(--ISNUMBER(SEARCH({"棚板","棚","アングル","ｱﾝｸﾞﾙ","使用不可","ケーブル","ｹｰﾌﾞﾙ","PatchPnael","パッチ","引き出し","引出","ブランク","ﾌﾞﾗﾝｸ","マネージ","ﾏﾈｰｼﾞ","PDU","ONU"},$F2&"")))>0)),"／同じUに他の機器(横並びなら正常)","")&IF(AND(M2<>"",COUNTIFS(回路定義!$A:$A,A2,回路定義!$B:$B,M2)=0),"／回路1が定義にない","")&IF(AND(P2<>"",COUNTIFS(回路定義!$A:$A,A2,回路定義!$B:$B,P2)=0),"／回路2が定義にない","")&IF(AND(S2<>"",COUNTIFS(回路定義!$A:$A,A2,回路定義!$B:$B,S2)=0),"／回路3が定義にない",""),2,300)))
A3: E24-S8-1 | B3: 両面 | C3: 38 | D3: 1 | E3: =IF(C3="","",C3+D3-1) | F3: DELLEMC R640-2 | G3: H1714831 | I3: Server | J3: 9.5 | V3: ○ | X3: 故障のため電源未投入 | Y3: =COUNT(N3,Q3,T3) | Z3: =IF(OR(K3="",NOT(ISNUMBER(K3))),"",K3*SUM(N3,Q3,T3)) | AA3: =IF(OR(Y3=0,N3=""),"",N3/Y3) | AB3: =IF(OR(Y3=0,Q3=""),"",Q3/Y3) | AC3: =IF(OR(Y3=0,T3=""),"",T3/Y3) | AD3: =IF(F3="","",IF((IF(AND(Y3=0,NOT(SUMPRODUCT(--ISNUMBER(SEARCH({"棚板","棚","アングル","ｱﾝｸﾞﾙ","使用不可","ケーブル","ｹｰﾌﾞﾙ","PatchPnael","パッチ","引き出し","引出","ブランク","ﾌﾞﾗﾝｸ","マネージ","ﾏﾈｰｼﾞ","PDU","ONU"},$F3&"")))>0),NOT(SUMPRODUCT(--ISNUMBER(SEARCH({"電源オフ","未投入","停止","未使用","撤去"},$X3&"")))>0)),"／電力が未記入","")&IF(AND(NOT(ISNUMBER(J3)),NOT(SUMPRODUCT(--ISNUMBER(SEARCH({"棚板","棚","アングル","ｱﾝｸﾞﾙ","使用不可","ケーブル","ｹｰﾌﾞﾙ","PatchPnael","パッチ","引き出し","引出","ブランク","ﾌﾞﾗﾝｸ","マネージ","ﾏﾈｰｼﾞ","PDU","ONU"},$F3&"")))>0)),"／重量が未記入","")&IF(AND(K3<>"",NOT(ISNUMBER(K3))),"／電圧が数値でない","")&IF(AND(N3<>"",NOT(ISNUMBER(N3))),"／電流が数値でない","")&IF(AND(C3<>"",C3<1),"／開始Uが1未満","")&IF(AND(E3<>"",E3>IFERROR(VLOOKUP(A3,ラック定義!$A:$B,2,FALSE),47)),"／総Uをはみ出す","")&IF(AND(A3<>"",COUNTIF(ラック定義!$A:$A,A3)=0),"／ラックが定義にない","")&IF(AND(SUMPRODUCT((機器台帳!$A$2:$A$400=$A3)*((機器台帳!$B$2:$B$400=$B3)+(機器台帳!$B$2:$B$400="両面")+($B3="両面")>0)*(機器台帳!$C$2:$C$400<=$C3+$D3-1)*(機器台帳!$C$2:$C$400+機器台帳!$D$2:$D$400-1>=$C3)*(機器台帳!$F$2:$F$400<>""))-1>0,NOT(SUMPRODUCT(--ISNUMBER(SEARCH({"棚板","棚","アングル","ｱﾝｸﾞﾙ","使用不可","ケーブル","ｹｰﾌﾞﾙ","PatchPnael","パッチ","引き出し","引出","ブランク","ﾌﾞﾗﾝｸ","マネージ","ﾏﾈｰｼﾞ","PDU","ONU"},$F3&"")))>0)),"／同じUに他の機器(横並びなら正常)","")&IF(AND(M3<>"",COUNTIFS(回路定義!$A:$A,A3,回路定義!$B:$B,M3)=0),"／回路1が定義にない","")&IF(AND(P3<>"",COUNTIFS(回路定義!$A:$A,A3,回路定義!$B:$B,P3)=0),"／回路2が定義にない","")&IF(AND(S3<>"",COUNTIFS(回路定義!$A:$A,A3,回路定義!$B:$B,S3)=0),"／回路3が定義にない",""))="","",MID(IF(AND(Y3=0,NOT(SUMPRODUCT(--ISNUMBER(SEARCH({"棚板","棚","アングル","ｱﾝｸﾞﾙ","使用不可","ケーブル","ｹｰﾌﾞﾙ","PatchPnael","パッチ","引き出し","引出","ブランク","ﾌﾞﾗﾝｸ","マネージ","ﾏﾈｰｼﾞ","PDU","ONU"},$F3&"")))>0),NOT(SUMPRODUCT(--ISNUMBER(SEARCH({"電源オフ","未投入","停止","未使用","撤去"},$X3&"")))>0)),"／電力が未記入","")&IF(AND(NOT(ISNUMBER(J3)),NOT(SUMPRODUCT(--ISNUMBER(SEARCH({"棚板","棚","アングル","ｱﾝｸﾞﾙ","使用不可","ケーブル","ｹｰﾌﾞﾙ","PatchPnael","パッチ","引き出し","引出","ブランク","ﾌﾞﾗﾝｸ","マネージ","ﾏﾈｰｼﾞ","PDU","ONU"},$F3&"")))>0)),"／重量が未記入","")&IF(AND(K3<>"",NOT(ISNUMBER(K3))),"／電圧が数値でない","")&IF(AND(N3<>"",NOT(ISNUMBER(N3))),"／電流が数値でない","")&IF(AND(C3<>"",C3<1),"／開始Uが1未満","")&IF(AND(E3<>"",E3>IFERROR(VLOOKUP(A3,ラック定義!$A:$B,2,FALSE),47)),"／総Uをはみ出す","")&IF(AND(A3<>"",COUNTIF(ラック定義!$A:$A,A3)=0),"／ラックが定義にない","")&IF(AND(SUMPRODUCT((機器台帳!$A$2:$A$400=$A3)*((機器台帳!$B$2:$B$400=$B3)+(機器台帳!$B$2:$B$400="両面")+($B3="両面")>0)*(機器台帳!$C$2:$C$400<=$C3+$D3-1)*(機器台帳!$C$2:$C$400+機器台帳!$D$2:$D$400-1>=$C3)*(機器台帳!$F$2:$F$400<>""))-1>0,NOT(SUMPRODUCT(--ISNUMBER(SEARCH({"棚板","棚","アングル","ｱﾝｸﾞﾙ","使用不可","ケーブル","ｹｰﾌﾞﾙ","PatchPnael","パッチ","引き出し","引出","ブランク","ﾌﾞﾗﾝｸ","マネージ","ﾏﾈｰｼﾞ","PDU","ONU"},$F3&"")))>0)),"／同じUに他の機器(横並びなら正常)","")&IF(AND(M3<>"",COUNTIFS(回路定義!$A:$A,A3,回路定義!$B:$B,M3)=0),"／回路1が定義にない","")&IF(AND(P3<>"",COUNTIFS(回路定義!$A:$A,A3,回路定義!$B:$B,P3)=0),"／回路2が定義にない","")&IF(AND(S3<>"",COUNTIFS(回路定義!$A:$A,A3,回路定義!$B:$B,S3)=0),"／回路3が定義にない",""),2,300)))
A4: E24-S8-1 | B4: 両面 | C4: 36 | D4: 1 | E4: =IF(C4="","",C4+D4-1) | F4: VxRail E560-6 | G4: H1806676 | H4: AdTech | I4: Server | J4: 9.5 | K4: 100 | L4: 2 | M4: 100V 20A （1） | N4: 3 | O4: 2 | V4: ○ | Y4: =COUNT(N4,Q4,T4) | Z4: =IF(OR(K4="",NOT(ISNUMBER(K4))),"",K4*SUM(N4,Q4,T4)) | AA4: =IF(OR(Y4=0,N4=""),"",N4/Y4) | AB4: =IF(OR(Y4=0,Q4=""),"",Q4/Y4) | AC4: =IF(OR(Y4=0,T4=""),"",T4/Y4) | AD4: =IF(F4="","",IF((IF(AND(Y4=0,NOT(SUMPRODUCT(--ISNUMBER(SEARCH({"棚板","棚","アングル","ｱﾝｸﾞﾙ","使用不可","ケーブル","ｹｰﾌﾞﾙ","PatchPnael","パッチ","引き出し","引出","ブランク","ﾌﾞﾗﾝｸ","マネージ","ﾏﾈｰｼﾞ","PDU","ONU"},$F4&"")))>0),NOT(SUMPRODUCT(--ISNUMBER(SEARCH({"電源オフ","未投入","停止","未使用","撤去"},$X4&"")))>0)),"／電力が未記入","")&IF(AND(NOT(ISNUMBER(J4)),NOT(SUMPRODUCT(--ISNUMBER(SEARCH({"棚板","棚","アングル","ｱﾝｸﾞﾙ","使用不可","ケーブル","ｹｰﾌﾞﾙ","PatchPnael","パッチ","引き出し","引出","ブランク","ﾌﾞﾗﾝｸ","マネージ","ﾏﾈｰｼﾞ","PDU","ONU"},$F4&"")))>0)),"／重量が未記入","")&IF(AND(K4<>"",NOT(ISNUMBER(K4))),"／電圧が数値でない","")&IF(AND(N4<>"",NOT(ISNUMBER(N4))),"／電流が数値でない","")&IF(AND(C4<>"",C4<1),"／開始Uが1未満","")&IF(AND(E4<>"",E4>IFERROR(VLOOKUP(A4,ラック定義!$A:$B,2,FALSE),47)),"／総Uをはみ出す","")&IF(AND(A4<>"",COUNTIF(ラック定義!$A:$A,A4)=0),"／ラックが定義にない","")&IF(AND(SUMPRODUCT((機器台帳!$A$2:$A$400=$A4)*((機器台帳!$B$2:$B$400=$B4)+(機器台帳!$B$2:$B$400="両面")+($B4="両面")>0)*(機器台帳!$C$2:$C$400<=$C4+$D4-1)*(機器台帳!$C$2:$C$400+機器台帳!$D$2:$D$400-1>=$C4)*(機器台帳!$F$2:$F$400<>""))-1>0,NOT(SUMPRODUCT(--ISNUMBER(SEARCH({"棚板","棚","アングル","ｱﾝｸﾞﾙ","使用不可","ケーブル","ｹｰﾌﾞﾙ","PatchPnael","パッチ","引き出し","引出","ブランク","ﾌﾞﾗﾝｸ","マネージ","ﾏﾈｰｼﾞ","PDU","ONU"},$F4&"")))>0)),"／同じUに他の機器(横並びなら正常)","")&IF(AND(M4<>"",COUNTIFS(回路定義!$A:$A,A4,回路定義!$B:$B,M4)=0),"／回路1が定義にない","")&IF(AND(P4<>"",COUNTIFS(回路定義!$A:$A,A4,回路定義!$B:$B,P4)=0),"／回路2が定義にない","")&IF(AND(S4<>"",COUNTIFS(回路定義!$A:$A,A4,回路定義!$B:$B,S4)=0),"／回路3が定義にない",""))="","",MID(IF(AND(Y4=0,NOT(SUMPRODUCT(--ISNUMBER(SEARCH({"棚板","棚","アングル","ｱﾝｸﾞﾙ","使用不可","ケーブル","ｹｰﾌﾞﾙ","PatchPnael","パッチ","引き出し","引出","ブランク","ﾌﾞﾗﾝｸ","マネージ","ﾏﾈｰｼﾞ","PDU","ONU"},$F4&"")))>0),NOT(SUMPRODUCT(--ISNUMBER(SEARCH({"電源オフ","未投入","停止","未使用","撤去"},$X4&"")))>0)),"／電力が未記入","")&IF(AND(NOT(ISNUMBER(J4)),NOT(SUMPRODUCT(--ISNUMBER(SEARCH({"棚板","棚","アングル","ｱﾝｸﾞﾙ","使用不可","ケーブル","ｹｰﾌﾞﾙ","PatchPnael","パッチ","引き出し","引出","ブランク","ﾌﾞﾗﾝｸ","マネージ","ﾏﾈｰｼﾞ","PDU","ONU"},$F4&"")))>0)),"／重量が未記入","")&IF(AND(K4<>"",NOT(ISNUMBER(K4))),"／電圧が数値でない","")&IF(AND(N4<>"",NOT(ISNUMBER(N4))),"／電流が数値でない","")&IF(AND(C4<>"",C4<1),"／開始Uが1未満","")&IF(AND(E4<>"",E4>IFERROR(VLOOKUP(A4,ラック定義!$A:$B,2,FALSE),47)),"／総Uをはみ出す","")&IF(AND(A4<>"",COUNTIF(ラック定義!$A:$A,A4)=0),"／ラックが定義にない","")&IF(AND(SUMPRODUCT((機器台帳!$A$2:$A$400=$A4)*((機器台帳!$B$2:$B$400=$B4)+(機器台帳!$B$2:$B$400="両面")+($B4="両面")>0)*(機器台帳!$C$2:$C$400<=$C4+$D4-1)*(機器台帳!$C$2:$C$400+機器台帳!$D$2:$D$400-1>=$C4)*(機器台帳!$F$2:$F$400<>""))-1>0,NOT(SUMPRODUCT(--ISNUMBER(SEARCH({"棚板","棚","アングル","ｱﾝｸﾞﾙ","使用不可","ケーブル","ｹｰﾌﾞﾙ","PatchPnael","パッチ","引き出し","引出","ブランク","ﾌﾞﾗﾝｸ","マネージ","ﾏﾈｰｼﾞ","PDU","ONU"},$F4&"")))>0)),"／同じUに他の機器(横並びなら正常)","")&IF(AND(M4<>"",COUNTIFS(回路定義!$A:$A,A4,回路定義!$B:$B,M4)=0),"／回路1が定義にない","")&IF(AND(P4<>"",COUNTIFS(回路定義!$A:$A,A4,回路定義!$B:$B,P4)=0),"／回路2が定義にない","")&IF(AND(S4<>"",COUNTIFS(回路定義!$A:$A,A4,回路定義!$B:$B,S4)=0),"／回路3が定義にない",""),2,300)))
A5: E24-S8-1 | B5: 両面 | C5: 35 | D5: 1 | E5: =IF(C5="","",C5+D5-1) | F5: VxRail E560-5 | G5: H1806677 | H5: AdTech | I5: Server | J5: 9.5 | K5: 100 | L5: 2 | M5: 100V 20A （1） | N5: 3 | O5: 2 | V5: ○ | Y5: =COUNT(N5,Q5,T5) | Z5: =IF(OR(K5="",NOT(ISNUMBER(K5))),"",K5*SUM(N5,Q5,T5)) | AA5: =IF(OR(Y5=0,N5=""),"",N5/Y5) | AB5: =IF(OR(Y5=0,Q5=""),"",Q5/Y5) | AC5: =IF(OR(Y5=0,T5=""),"",T5/Y5) | AD5: =IF(F5="","",IF((IF(AND(Y5=0,NOT(SUMPRODUCT(--ISNUMBER(SEARCH({"棚板","棚","アングル","ｱﾝｸﾞﾙ","使用不可","ケーブル","ｹｰﾌﾞﾙ","PatchPnael","パッチ","引き出し","引出","ブランク","ﾌﾞﾗﾝｸ","マネージ","ﾏﾈｰｼﾞ","PDU","ONU"},$F5&"")))>0),NOT(SUMPRODUCT(--ISNUMBER(SEARCH({"電源オフ","未投入","停止","未使用","撤去"},$X5&"")))>0)),"／電力が未記入","")&IF(AND(NOT(ISNUMBER(J5)),NOT(SUMPRODUCT(--ISNUMBER(SEARCH({"棚板","棚","アングル","ｱﾝｸﾞﾙ","使用不可","ケーブル","ｹｰﾌﾞﾙ","PatchPnael","パッチ","引き出し","引出","ブランク","ﾌﾞﾗﾝｸ","マネージ","ﾏﾈｰｼﾞ","PDU","ONU"},$F5&"")))>0)),"／重量が未記入","")&IF(AND(K5<>"",NOT(ISNUMBER(K5))),"／電圧が数値でない","")&IF(AND(N5<>"",NOT(ISNUMBER(N5))),"／電流が数値でない","")&IF(AND(C5<>"",C5<1),"／開始Uが1未満","")&IF(AND(E5<>"",E5>IFERROR(VLOOKUP(A5,ラック定義!$A:$B,2,FALSE),47)),"／総Uをはみ出す","")&IF(AND(A5<>"",COUNTIF(ラック定義!$A:$A,A5)=0),"／ラックが定義にない","")&IF(AND(SUMPRODUCT((機器台帳!$A$2:$A$400=$A5)*((機器台帳!$B$2:$B$400=$B5)+(機器台帳!$B$2:$B$400="両面")+($B5="両面")>0)*(機器台帳!$C$2:$C$400<=$C5+$D5-1)*(機器台帳!$C$2:$C$400+機器台帳!$D$2:$D$400-1>=$C5)*(機器台帳!$F$2:$F$400<>""))-1>0,NOT(SUMPRODUCT(--ISNUMBER(SEARCH({"棚板","棚","アングル","ｱﾝｸﾞﾙ","使用不可","ケーブル","ｹｰﾌﾞﾙ","PatchPnael","パッチ","引き出し","引出","ブランク","ﾌﾞﾗﾝｸ","マネージ","ﾏﾈｰｼﾞ","PDU","ONU"},$F5&"")))>0)),"／同じUに他の機器(横並びなら正常)","")&IF(AND(M5<>"",COUNTIFS(回路定義!$A:$A,A5,回路定義!$B:$B,M5)=0),"／回路1が定義にない","")&IF(AND(P5<>"",COUNTIFS(回路定義!$A:$A,A5,回路定義!$B:$B,P5)=0),"／回路2が定義にない","")&IF(AND(S5<>"",COUNTIFS(回路定義!$A:$A,A5,回路定義!$B:$B,S5)=0),"／回路3が定義にない",""))="","",MID(IF(AND(Y5=0,NOT(SUMPRODUCT(--ISNUMBER(SEARCH({"棚板","棚","アングル","ｱﾝｸﾞﾙ","使用不可","ケーブル","ｹｰﾌﾞﾙ","PatchPnael","パッチ","引き出し","引出","ブランク","ﾌﾞﾗﾝｸ","マネージ","ﾏﾈｰｼﾞ","PDU","ONU"},$F5&"")))>0),NOT(SUMPRODUCT(--ISNUMBER(SEARCH({"電源オフ","未投入","停止","未使用","撤去"},$X5&"")))>0)),"／電力が未記入","")&IF(AND(NOT(ISNUMBER(J5)),NOT(SUMPRODUCT(--ISNUMBER(SEARCH({"棚板","棚","アングル","ｱﾝｸﾞﾙ","使用不可","ケーブル","ｹｰﾌﾞﾙ","PatchPnael","パッチ","引き出し","引出","ブランク","ﾌﾞﾗﾝｸ","マネージ","ﾏﾈｰｼﾞ","PDU","ONU"},$F5&"")))>0)),"／重量が未記入","")&IF(AND(K5<>"",NOT(ISNUMBER(K5))),"／電圧が数値でない","")&IF(AND(N5<>"",NOT(ISNUMBER(N5))),"／電流が数値でない","")&IF(AND(C5<>"",C5<1),"／開始Uが1未満","")&IF(AND(E5<>"",E5>IFERROR(VLOOKUP(A5,ラック定義!$A:$B,2,FALSE),47)),"／総Uをはみ出す","")&IF(AND(A5<>"",COUNTIF(ラック定義!$A:$A,A5)=0),"／ラックが定義にない","")&IF(AND(SUMPRODUCT((機器台帳!$A$2:$A$400=$A5)*((機器台帳!$B$2:$B$400=$B5)+(機器台帳!$B$2:$B$400="両面")+($B5="両面")>0)*(機器台帳!$C$2:$C$400<=$C5+$D5-1)*(機器台帳!$C$2:$C$400+機器台帳!$D$2:$D$400-1>=$C5)*(機器台帳!$F$2:$F$400<>""))-1>0,NOT(SUMPRODUCT(--ISNUMBER(SEARCH({"棚板","棚","アングル","ｱﾝｸﾞﾙ","使用不可","ケーブル","ｹｰﾌﾞﾙ","PatchPnael","パッチ","引き出し","引出","ブランク","ﾌﾞﾗﾝｸ","マネージ","ﾏﾈｰｼﾞ","PDU","ONU"},$F5&"")))>0)),"／同じUに他の機器(横並びなら正常)","")&IF(AND(M5<>"",COUNTIFS(回路定義!$A:$A,A5,回路定義!$B:$B,M5)=0),"／回路1が定義にない","")&IF(AND(P5<>"",COUNTIFS(回路定義!$A:$A,A5,回路定義!$B:$B,P5)=0),"／回路2が定義にない","")&IF(AND(S5<>"",COUNTIFS(回路定義!$A:$A,A5,回路定義!$B:$B,S5)=0),"／回路3が定義にない",""),2,300)))
A6: E24-S8-1 | B6: 両面 | C6: 34 | D6: 1 | E6: =IF(C6="","",C6+D6-1) | F6: VxRail E560-1 | G6: H1806678 | H6: AdTech | I6: Server | J6: 9.5 | K6: 100 | L6: 2 | M6: 100V 20A （1） | N6: 3 | O6: 2 | V6: ○ | Y6: =COUNT(N6,Q6,T6) | Z6: =IF(OR(K6="",NOT(ISNUMBER(K6))),"",K6*SUM(N6,Q6,T6)) | AA6: =IF(OR(Y6=0,N6=""),"",N6/Y6) | AB6: =IF(OR(Y6=0,Q6=""),"",Q6/Y6) | AC6: =IF(OR(Y6=0,T6=""),"",T6/Y6) | AD6: =IF(F6="","",IF((IF(AND(Y6=0,NOT(SUMPRODUCT(--ISNUMBER(SEARCH({"棚板","棚","アングル","ｱﾝｸﾞﾙ","使用不可","ケーブル","ｹｰﾌﾞﾙ","PatchPnael","パッチ","引き出し","引出","ブランク","ﾌﾞﾗﾝｸ","マネージ","ﾏﾈｰｼﾞ","PDU","ONU"},$F6&"")))>0),NOT(SUMPRODUCT(--ISNUMBER(SEARCH({"電源オフ","未投入","停止","未使用","撤去"},$X6&"")))>0)),"／電力が未記入","")&IF(AND(NOT(ISNUMBER(J6)),NOT(SUMPRODUCT(--ISNUMBER(SEARCH({"棚板","棚","アングル","ｱﾝｸﾞﾙ","使用不可","ケーブル","ｹｰﾌﾞﾙ","PatchPnael","パッチ","引き出し","引出","ブランク","ﾌﾞﾗﾝｸ","マネージ","ﾏﾈｰｼﾞ","PDU","ONU"},$F6&"")))>0)),"／重量が未記入","")&IF(AND(K6<>"",NOT(ISNUMBER(K6))),"／電圧が数値でない","")&IF(AND(N6<>"",NOT(ISNUMBER(N6))),"／電流が数値でない","")&IF(AND(C6<>"",C6<1),"／開始Uが1未満","")&IF(AND(E6<>"",E6>IFERROR(VLOOKUP(A6,ラック定義!$A:$B,2,FALSE),47)),"／総Uをはみ出す","")&IF(AND(A6<>"",COUNTIF(ラック定義!$A:$A,A6)=0),"／ラックが定義にない","")&IF(AND(SUMPRODUCT((機器台帳!$A$2:$A$400=$A6)*((機器台帳!$B$2:$B$400=$B6)+(機器台帳!$B$2:$B$400="両面")+($B6="両面")>0)*(機器台帳!$C$2:$C$400<=$C6+$D6-1)*(機器台帳!$C$2:$C$400+機器台帳!$D$2:$D$400-1>=$C6)*(機器台帳!$F$2:$F$400<>""))-1>0,NOT(SUMPRODUCT(--ISNUMBER(SEARCH({"棚板","棚","アングル","ｱﾝｸﾞﾙ","使用不可","ケーブル","ｹｰﾌﾞﾙ","PatchPnael","パッチ","引き出し","引出","ブランク","ﾌﾞﾗﾝｸ","マネージ","ﾏﾈｰｼﾞ","PDU","ONU"},$F6&"")))>0)),"／同じUに他の機器(横並びなら正常)","")&IF(AND(M6<>"",COUNTIFS(回路定義!$A:$A,A6,回路定義!$B:$B,M6)=0),"／回路1が定義にない","")&IF(AND(P6<>"",COUNTIFS(回路定義!$A:$A,A6,回路定義!$B:$B,P6)=0),"／回路2が定義にない","")&IF(AND(S6<>"",COUNTIFS(回路定義!$A:$A,A6,回路定義!$B:$B,S6)=0),"／回路3が定義にない",""))="","",MID(IF(AND(Y6=0,NOT(SUMPRODUCT(--ISNUMBER(SEARCH({"棚板","棚","アングル","ｱﾝｸﾞﾙ","使用不可","ケーブル","ｹｰﾌﾞﾙ","PatchPnael","パッチ","引き出し","引出","ブランク","ﾌﾞﾗﾝｸ","マネージ","ﾏﾈｰｼﾞ","PDU","ONU"},$F6&"")))>0),NOT(SUMPRODUCT(--ISNUMBER(SEARCH({"電源オフ","未投入","停止","未使用","撤去"},$X6&"")))>0)),"／電力が未記入","")&IF(AND(NOT(ISNUMBER(J6)),NOT(SUMPRODUCT(--ISNUMBER(SEARCH({"棚板","棚","アングル","ｱﾝｸﾞﾙ","使用不可","ケーブル","ｹｰﾌﾞﾙ","PatchPnael","パッチ","引き出し","引出","ブランク","ﾌﾞﾗﾝｸ","マネージ","ﾏﾈｰｼﾞ","PDU","ONU"},$F6&"")))>0)),"／重量が未記入","")&IF(AND(K6<>"",NOT(ISNUMBER(K6))),"／電圧が数値でない","")&IF(AND(N6<>"",NOT(ISNUMBER(N6))),"／電流が数値でない","")&IF(AND(C6<>"",C6<1),"／開始Uが1未満","")&IF(AND(E6<>"",E6>IFERROR(VLOOKUP(A6,ラック定義!$A:$B,2,FALSE),47)),"／総Uをはみ出す","")&IF(AND(A6<>"",COUNTIF(ラック定義!$A:$A,A6)=0),"／ラックが定義にない","")&IF(AND(SUMPRODUCT((機器台帳!$A$2:$A$400=$A6)*((機器台帳!$B$2:$B$400=$B6)+(機器台帳!$B$2:$B$400="両面")+($B6="両面")>0)*(機器台帳!$C$2:$C$400<=$C6+$D6-1)*(機器台帳!$C$2:$C$400+機器台帳!$D$2:$D$400-1>=$C6)*(機器台帳!$F$2:$F$400<>""))-1>0,NOT(SUMPRODUCT(--ISNUMBER(SEARCH({"棚板","棚","アングル","ｱﾝｸﾞﾙ","使用不可","ケーブル","ｹｰﾌﾞﾙ","PatchPnael","パッチ","引き出し","引出","ブランク","ﾌﾞﾗﾝｸ","マネージ","ﾏﾈｰｼﾞ","PDU","ONU"},$F6&"")))>0)),"／同じUに他の機器(横並びなら正常)","")&IF(AND(M6<>"",COUNTIFS(回路定義!$A:$A,A6,回路定義!$B:$B,M6)=0),"／回路1が定義にない","")&IF(AND(P6<>"",COUNTIFS(回路定義!$A:$A,A6,回路定義!$B:$B,P6)=0),"／回路2が定義にない","")&IF(AND(S6<>"",COUNTIFS(回路定義!$A:$A,A6,回路定義!$B:$B,S6)=0),"／回路3が定義にない",""),2,300)))
A7: E24-S8-1 | B7: 両面 | C7: 32 | D7: 1 | E7: =IF(C7="","",C7+D7-1) | F7: VxRail E560-4 | G7: H1809660 | H7: AdTech | I7: Server | J7: 9.5 | K7: 100 | L7: 2 | M7: 100V 20A （2） | N7: 3 | O7: 2 | V7: ○ | Y7: =COUNT(N7,Q7,T7) | Z7: =IF(OR(K7="",NOT(ISNUMBER(K7))),"",K7*SUM(N7,Q7,T7)) | AA7: =IF(OR(Y7=0,N7=""),"",N7/Y7) | AB7: =IF(OR(Y7=0,Q7=""),"",Q7/Y7) | AC7: =IF(OR(Y7=0,T7=""),"",T7/Y7) | AD7: =IF(F7="","",IF((IF(AND(Y7=0,NOT(SUMPRODUCT(--ISNUMBER(SEARCH({"棚板","棚","アングル","ｱﾝｸﾞﾙ","使用不可","ケーブル","ｹｰﾌﾞﾙ","PatchPnael","パッチ","引き出し","引出","ブランク","ﾌﾞﾗﾝｸ","マネージ","ﾏﾈｰｼﾞ","PDU","ONU"},$F7&"")))>0),NOT(SUMPRODUCT(--ISNUMBER(SEARCH({"電源オフ","未投入","停止","未使用","撤去"},$X7&"")))>0)),"／電力が未記入","")&IF(AND(NOT(ISNUMBER(J7)),NOT(SUMPRODUCT(--ISNUMBER(SEARCH({"棚板","棚","アングル","ｱﾝｸﾞﾙ","使用不可","ケーブル","ｹｰﾌﾞﾙ","PatchPnael","パッチ","引き出し","引出","ブランク","ﾌﾞﾗﾝｸ","マネージ","ﾏﾈｰｼﾞ","PDU","ONU"},$F7&"")))>0)),"／重量が未記入","")&IF(AND(K7<>"",NOT(ISNUMBER(K7))),"／電圧が数値でない","")&IF(AND(N7<>"",NOT(ISNUMBER(N7))),"／電流が数値でない","")&IF(AND(C7<>"",C7<1),"／開始Uが1未満","")&IF(AND(E7<>"",E7>IFERROR(VLOOKUP(A7,ラック定義!$A:$B,2,FALSE),47)),"／総Uをはみ出す","")&IF(AND(A7<>"",COUNTIF(ラック定義!$A:$A,A7)=0),"／ラックが定義にない","")&IF(AND(SUMPRODUCT((機器台帳!$A$2:$A$400=$A7)*((機器台帳!$B$2:$B$400=$B7)+(機器台帳!$B$2:$B$400="両面")+($B7="両面")>0)*(機器台帳!$C$2:$C$400<=$C7+$D7-1)*(機器台帳!$C$2:$C$400+機器台帳!$D$2:$D$400-1>=$C7)*(機器台帳!$F$2:$F$400<>""))-1>0,NOT(SUMPRODUCT(--ISNUMBER(SEARCH({"棚板","棚","アングル","ｱﾝｸﾞﾙ","使用不可","ケーブル","ｹｰﾌﾞﾙ","PatchPnael","パッチ","引き出し","引出","ブランク","ﾌﾞﾗﾝｸ","マネージ","ﾏﾈｰｼﾞ","PDU","ONU"},$F7&"")))>0)),"／同じUに他の機器(横並びなら正常)","")&IF(AND(M7<>"",COUNTIFS(回路定義!$A:$A,A7,回路定義!$B:$B,M7)=0),"／回路1が定義にない","")&IF(AND(P7<>"",COUNTIFS(回路定義!$A:$A,A7,回路定義!$B:$B,P7)=0),"／回路2が定義にない","")&IF(AND(S7<>"",COUNTIFS(回路定義!$A:$A,A7,回路定義!$B:$B,S7)=0),"／回路3が定義にない",""))="","",MID(IF(AND(Y7=0,NOT(SUMPRODUCT(--ISNUMBER(SEARCH({"棚板","棚","アングル","ｱﾝｸﾞﾙ","使用不可","ケーブル","ｹｰﾌﾞﾙ","PatchPnael","パッチ","引き出し","引出","ブランク","ﾌﾞﾗﾝｸ","マネージ","ﾏﾈｰｼﾞ","PDU","ONU"},$F7&"")))>0),NOT(SUMPRODUCT(--ISNUMBER(SEARCH({"電源オフ","未投入","停止","未使用","撤去"},$X7&"")))>0)),"／電力が未記入","")&IF(AND(NOT(ISNUMBER(J7)),NOT(SUMPRODUCT(--ISNUMBER(SEARCH({"棚板","棚","アングル","ｱﾝｸﾞﾙ","使用不可","ケーブル","ｹｰﾌﾞﾙ","PatchPnael","パッチ","引き出し","引出","ブランク","ﾌﾞﾗﾝｸ","マネージ","ﾏﾈｰｼﾞ","PDU","ONU"},$F7&"")))>0)),"／重量が未記入","")&IF(AND(K7<>"",NOT(ISNUMBER(K7))),"／電圧が数値でない","")&IF(AND(N7<>"",NOT(ISNUMBER(N7))),"／電流が数値でない","")&IF(AND(C7<>"",C7<1),"／開始Uが1未満","")&IF(AND(E7<>"",E7>IFERROR(VLOOKUP(A7,ラック定義!$A:$B,2,FALSE),47)),"／総Uをはみ出す","")&IF(AND(A7<>"",COUNTIF(ラック定義!$A:$A,A7)=0),"／ラックが定義にない","")&IF(AND(SUMPRODUCT((機器台帳!$A$2:$A$400=$A7)*((機器台帳!$B$2:$B$400=$B7)+(機器台帳!$B$2:$B$400="両面")+($B7="両面")>0)*(機器台帳!$C$2:$C$400<=$C7+$D7-1)*(機器台帳!$C$2:$C$400+機器台帳!$D$2:$D$400-1>=$C7)*(機器台帳!$F$2:$F$400<>""))-1>0,NOT(SUMPRODUCT(--ISNUMBER(SEARCH({"棚板","棚","アングル","ｱﾝｸﾞﾙ","使用不可","ケーブル","ｹｰﾌﾞﾙ","PatchPnael","パッチ","引き出し","引出","ブランク","ﾌﾞﾗﾝｸ","マネージ","ﾏﾈｰｼﾞ","PDU","ONU"},$F7&"")))>0)),"／同じUに他の機器(横並びなら正常)","")&IF(AND(M7<>"",COUNTIFS(回路定義!$A:$A,A7,回路定義!$B:$B,M7)=0),"／回路1が定義にない","")&IF(AND(P7<>"",COUNTIFS(回路定義!$A:$A,A7,回路定義!$B:$B,P7)=0),"／回路2が定義にない","")&IF(AND(S7<>"",COUNTIFS(回路定義!$A:$A,A7,回路定義!$B:$B,S7)=0),"／回路3が定義にない",""),2,300)))
A8: E24-S8-1 | B8: 両面 | C8: 31 | D8: 1 | E8: =IF(C8="","",C8+D8-1) | F8: VxRail E560-2 | G8: H1809661 | H8: AdTech | I8: Server | J8: 9.5 | K8: 100 | L8: 2 | M8: 100V 20A （2） | N8: 3 | O8: 2 | V8: ○ | Y8: =COUNT(N8,Q8,T8) | Z8: =IF(OR(K8="",NOT(ISNUMBER(K8))),"",K8*SUM(N8,Q8,T8)) | AA8: =IF(OR(Y8=0,N8=""),"",N8/Y8) | AB8: =IF(OR(Y8=0,Q8=""),"",Q8/Y8) | AC8: =IF(OR(Y8=0,T8=""),"",T8/Y8) | AD8: =IF(F8="","",IF((IF(AND(Y8=0,NOT(SUMPRODUCT(--ISNUMBER(SEARCH({"棚板","棚","アングル","ｱﾝｸﾞﾙ","使用不可","ケーブル","ｹｰﾌﾞﾙ","PatchPnael","パッチ","引き出し","引出","ブランク","ﾌﾞﾗﾝｸ","マネージ","ﾏﾈｰｼﾞ","PDU","ONU"},$F8&"")))>0),NOT(SUMPRODUCT(--ISNUMBER(SEARCH({"電源オフ","未投入","停止","未使用","撤去"},$X8&"")))>0)),"／電力が未記入","")&IF(AND(NOT(ISNUMBER(J8)),NOT(SUMPRODUCT(--ISNUMBER(SEARCH({"棚板","棚","アングル","ｱﾝｸﾞﾙ","使用不可","ケーブル","ｹｰﾌﾞﾙ","PatchPnael","パッチ","引き出し","引出","ブランク","ﾌﾞﾗﾝｸ","マネージ","ﾏﾈｰｼﾞ","PDU","ONU"},$F8&"")))>0)),"／重量が未記入","")&IF(AND(K8<>"",NOT(ISNUMBER(K8))),"／電圧が数値でない","")&IF(AND(N8<>"",NOT(ISNUMBER(N8))),"／電流が数値でない","")&IF(AND(C8<>"",C8<1),"／開始Uが1未満","")&IF(AND(E8<>"",E8>IFERROR(VLOOKUP(A8,ラック定義!$A:$B,2,FALSE),47)),"／総Uをはみ出す","")&IF(AND(A8<>"",COUNTIF(ラック定義!$A:$A,A8)=0),"／ラックが定義にない","")&IF(AND(SUMPRODUCT((機器台帳!$A$2:$A$400=$A8)*((機器台帳!$B$2:$B$400=$B8)+(機器台帳!$B$2:$B$400="両面")+($B8="両面")>0)*(機器台帳!$C$2:$C$400<=$C8+$D8-1)*(機器台帳!$C$2:$C$400+機器台帳!$D$2:$D$400-1>=$C8)*(機器台帳!$F$2:$F$400<>""))-1>0,NOT(SUMPRODUCT(--ISNUMBER(SEARCH({"棚板","棚","アングル","ｱﾝｸﾞﾙ","使用不可","ケーブル","ｹｰﾌﾞﾙ","PatchPnael","パッチ","引き出し","引出","ブランク","ﾌﾞﾗﾝｸ","マネージ","ﾏﾈｰｼﾞ","PDU","ONU"},$F8&"")))>0)),"／同じUに他の機器(横並びなら正常)","")&IF(AND(M8<>"",COUNTIFS(回路定義!$A:$A,A8,回路定義!$B:$B,M8)=0),"／回路1が定義にない","")&IF(AND(P8<>"",COUNTIFS(回路定義!$A:$A,A8,回路定義!$B:$B,P8)=0),"／回路2が定義にない","")&IF(AND(S8<>"",COUNTIFS(回路定義!$A:$A,A8,回路定義!$B:$B,S8)=0),"／回路3が定義にない",""))="","",MID(IF(AND(Y8=0,NOT(SUMPRODUCT(--ISNUMBER(SEARCH({"棚板","棚","アングル","ｱﾝｸﾞﾙ","使用不可","ケーブル","ｹｰﾌﾞﾙ","PatchPnael","パッチ","引き出し","引出","ブランク","ﾌﾞﾗﾝｸ","マネージ","ﾏﾈｰｼﾞ","PDU","ONU"},$F8&"")))>0),NOT(SUMPRODUCT(--ISNUMBER(SEARCH({"電源オフ","未投入","停止","未使用","撤去"},$X8&"")))>0)),"／電力が未記入","")&IF(AND(NOT(ISNUMBER(J8)),NOT(SUMPRODUCT(--ISNUMBER(SEARCH({"棚板","棚","アングル","ｱﾝｸﾞﾙ","使用不可","ケーブル","ｹｰﾌﾞﾙ","PatchPnael","パッチ","引き出し","引出","ブランク","ﾌﾞﾗﾝｸ","マネージ","ﾏﾈｰｼﾞ","PDU","ONU"},$F8&"")))>0)),"／重量が未記入","")&IF(AND(K8<>"",NOT(ISNUMBER(K8))),"／電圧が数値でない","")&IF(AND(N8<>"",NOT(ISNUMBER(N8))),"／電流が数値でない","")&IF(AND(C8<>"",C8<1),"／開始Uが1未満","")&IF(AND(E8<>"",E8>IFERROR(VLOOKUP(A8,ラック定義!$A:$B,2,FALSE),47)),"／総Uをはみ出す","")&IF(AND(A8<>"",COUNTIF(ラック定義!$A:$A,A8)=0),"／ラックが定義にない","")&IF(AND(SUMPRODUCT((機器台帳!$A$2:$A$400=$A8)*((機器台帳!$B$2:$B$400=$B8)+(機器台帳!$B$2:$B$400="両面")+($B8="両面")>0)*(機器台帳!$C$2:$C$400<=$C8+$D8-1)*(機器台帳!$C$2:$C$400+機器台帳!$D$2:$D$400-1>=$C8)*(機器台帳!$F$2:$F$400<>""))-1>0,NOT(SUMPRODUCT(--ISNUMBER(SEARCH({"棚板","棚","アングル","ｱﾝｸﾞﾙ","使用不可","ケーブル","ｹｰﾌﾞﾙ","PatchPnael","パッチ","引き出し","引出","ブランク","ﾌﾞﾗﾝｸ","マネージ","ﾏﾈｰｼﾞ","PDU","ONU"},$F8&"")))>0)),"／同じUに他の機器(横並びなら正常)","")&IF(AND(M8<>"",COUNTIFS(回路定義!$A:$A,A8,回路定義!$B:$B,M8)=0),"／回路1が定義にない","")&IF(AND(P8<>"",COUNTIFS(回路定義!$A:$A,A8,回路定義!$B:$B,P8)=0),"／回路2が定義にない","")&IF(AND(S8<>"",COUNTIFS(回路定義!$A:$A,A8,回路定義!$B:$B,S8)=0),"／回路3が定義にない",""),2,300)))
A9: E24-S8-1 | B9: 両面 | C9: 30 | D9: 1 | E9: =IF(C9="","",C9+D9-1) | F9: VxRail E560-3 | G9: H1809662 | H9: AdTech | I9: Server | J9: 9.5 | K9: 100 | L9: 2 | M9: 100V 20A （2） | N9: 3 | O9: 2 | V9: ○ | Y9: =COUNT(N9,Q9,T9) | Z9: =IF(OR(K9="",NOT(ISNUMBER(K9))),"",K9*SUM(N9,Q9,T9)) | AA9: =IF(OR(Y9=0,N9=""),"",N9/Y9) | AB9: =IF(OR(Y9=0,Q9=""),"",Q9/Y9) | AC9: =IF(OR(Y9=0,T9=""),"",T9/Y9) | AD9: =IF(F9="","",IF((IF(AND(Y9=0,NOT(SUMPRODUCT(--ISNUMBER(SEARCH({"棚板","棚","アングル","ｱﾝｸﾞﾙ","使用不可","ケーブル","ｹｰﾌﾞﾙ","PatchPnael","パッチ","引き出し","引出","ブランク","ﾌﾞﾗﾝｸ","マネージ","ﾏﾈｰｼﾞ","PDU","ONU"},$F9&"")))>0),NOT(SUMPRODUCT(--ISNUMBER(SEARCH({"電源オフ","未投入","停止","未使用","撤去"},$X9&"")))>0)),"／電力が未記入","")&IF(AND(NOT(ISNUMBER(J9)),NOT(SUMPRODUCT(--ISNUMBER(SEARCH({"棚板","棚","アングル","ｱﾝｸﾞﾙ","使用不可","ケーブル","ｹｰﾌﾞﾙ","PatchPnael","パッチ","引き出し","引出","ブランク","ﾌﾞﾗﾝｸ","マネージ","ﾏﾈｰｼﾞ","PDU","ONU"},$F9&"")))>0)),"／重量が未記入","")&IF(AND(K9<>"",NOT(ISNUMBER(K9))),"／電圧が数値でない","")&IF(AND(N9<>"",NOT(ISNUMBER(N9))),"／電流が数値でない","")&IF(AND(C9<>"",C9<1),"／開始Uが1未満","")&IF(AND(E9<>"",E9>IFERROR(VLOOKUP(A9,ラック定義!$A:$B,2,FALSE),47)),"／総Uをはみ出す","")&IF(AND(A9<>"",COUNTIF(ラック定義!$A:$A,A9)=0),"／ラックが定義にない","")&IF(AND(SUMPRODUCT((機器台帳!$A$2:$A$400=$A9)*((機器台帳!$B$2:$B$400=$B9)+(機器台帳!$B$2:$B$400="両面")+($B9="両面")>0)*(機器台帳!$C$2:$C$400<=$C9+$D9-1)*(機器台帳!$C$2:$C$400+機器台帳!$D$2:$D$400-1>=$C9)*(機器台帳!$F$2:$F$400<>""))-1>0,NOT(SUMPRODUCT(--ISNUMBER(SEARCH({"棚板","棚","アングル","ｱﾝｸﾞﾙ","使用不可","ケーブル","ｹｰﾌﾞﾙ","PatchPnael","パッチ","引き出し","引出","ブランク","ﾌﾞﾗﾝｸ","マネージ","ﾏﾈｰｼﾞ","PDU","ONU"},$F9&"")))>0)),"／同じUに他の機器(横並びなら正常)","")&IF(AND(M9<>"",COUNTIFS(回路定義!$A:$A,A9,回路定義!$B:$B,M9)=0),"／回路1が定義にない","")&IF(AND(P9<>"",COUNTIFS(回路定義!$A:$A,A9,回路定義!$B:$B,P9)=0),"／回路2が定義にない","")&IF(AND(S9<>"",COUNTIFS(回路定義!$A:$A,A9,回路定義!$B:$B,S9)=0),"／回路3が定義にない",""))="","",MID(IF(AND(Y9=0,NOT(SUMPRODUCT(--ISNUMBER(SEARCH({"棚板","棚","アングル","ｱﾝｸﾞﾙ","使用不可","ケーブル","ｹｰﾌﾞﾙ","PatchPnael","パッチ","引き出し","引出","ブランク","ﾌﾞﾗﾝｸ","マネージ","ﾏﾈｰｼﾞ","PDU","ONU"},$F9&"")))>0),NOT(SUMPRODUCT(--ISNUMBER(SEARCH({"電源オフ","未投入","停止","未使用","撤去"},$X9&"")))>0)),"／電力が未記入","")&IF(AND(NOT(ISNUMBER(J9)),NOT(SUMPRODUCT(--ISNUMBER(SEARCH({"棚板","棚","アングル","ｱﾝｸﾞﾙ","使用不可","ケーブル","ｹｰﾌﾞﾙ","PatchPnael","パッチ","引き出し","引出","ブランク","ﾌﾞﾗﾝｸ","マネージ","ﾏﾈｰｼﾞ","PDU","ONU"},$F9&"")))>0)),"／重量が未記入","")&IF(AND(K9<>"",NOT(ISNUMBER(K9))),"／電圧が数値でない","")&IF(AND(N9<>"",NOT(ISNUMBER(N9))),"／電流が数値でない","")&IF(AND(C9<>"",C9<1),"／開始Uが1未満","")&IF(AND(E9<>"",E9>IFERROR(VLOOKUP(A9,ラック定義!$A:$B,2,FALSE),47)),"／総Uをはみ出す","")&IF(AND(A9<>"",COUNTIF(ラック定義!$A:$A,A9)=0),"／ラックが定義にない","")&IF(AND(SUMPRODUCT((機器台帳!$A$2:$A$400=$A9)*((機器台帳!$B$2:$B$400=$B9)+(機器台帳!$B$2:$B$400="両面")+($B9="両面")>0)*(機器台帳!$C$2:$C$400<=$C9+$D9-1)*(機器台帳!$C$2:$C$400+機器台帳!$D$2:$D$400-1>=$C9)*(機器台帳!$F$2:$F$400<>""))-1>0,NOT(SUMPRODUCT(--ISNUMBER(SEARCH({"棚板","棚","アングル","ｱﾝｸﾞﾙ","使用不可","ケーブル","ｹｰﾌﾞﾙ","PatchPnael","パッチ","引き出し","引出","ブランク","ﾌﾞﾗﾝｸ","マネージ","ﾏﾈｰｼﾞ","PDU","ONU"},$F9&"")))>0)),"／同じUに他の機器(横並びなら正常)","")&IF(AND(M9<>"",COUNTIFS(回路定義!$A:$A,A9,回路定義!$B:$B,M9)=0),"／回路1が定義にない","")&IF(AND(P9<>"",COUNTIFS(回路定義!$A:$A,A9,回路定義!$B:$B,P9)=0),"／回路2が定義にない","")&IF(AND(S9<>"",COUNTIFS(回路定義!$A:$A,A9,回路定義!$B:$B,S9)=0),"／回路3が定義にない",""),2,300)))
A10: E24-S8-1 | B10: 両面 | C10: 16 | D10: 2 | E10: =IF(C10="","",C10+D10-1) | F10: PowerSTORE5000X | G10: H2005294 | I10: Storage | J10: 20 | K10: 200 | L10: 2 | M10: 200V 30A （1） | N10: 3 | O10: 2 | Y10: =COUNT(N10,Q10,T10) | Z10: =IF(OR(K10="",NOT(ISNUMBER(K10))),"",K10*SUM(N10,Q10,T10)) | AA10: =IF(OR(Y10=0,N10=""),"",N10/Y10) | AB10: =IF(OR(Y10=0,Q10=""),"",Q10/Y10) | AC10: =IF(OR(Y10=0,T10=""),"",T10/Y10) | AD10: =IF(F10="","",IF((IF(AND(Y10=0,NOT(SUMPRODUCT(--ISNUMBER(SEARCH({"棚板","棚","アングル","ｱﾝｸﾞﾙ","使用不可","ケーブル","ｹｰﾌﾞﾙ","PatchPnael","パッチ","引き出し","引出","ブランク","ﾌﾞﾗﾝｸ","マネージ","ﾏﾈｰｼﾞ","PDU","ONU"},$F10&"")))>0),NOT(SUMPRODUCT(--ISNUMBER(SEARCH({"電源オフ","未投入","停止","未使用","撤去"},$X10&"")))>0)),"／電力が未記入","")&IF(AND(NOT(ISNUMBER(J10)),NOT(SUMPRODUCT(--ISNUMBER(SEARCH({"棚板","棚","アングル","ｱﾝｸﾞﾙ","使用不可","ケーブル","ｹｰﾌﾞﾙ","PatchPnael","パッチ","引き出し","引出","ブランク","ﾌﾞﾗﾝｸ","マネージ","ﾏﾈｰｼﾞ","PDU","ONU"},$F10&"")))>0)),"／重量が未記入","")&IF(AND(K10<>"",NOT(ISNUMBER(K10))),"／電圧が数値でない","")&IF(AND(N10<>"",NOT(ISNUMBER(N10))),"／電流が数値でない","")&IF(AND(C10<>"",C10<1),"／開始Uが1未満","")&IF(AND(E10<>"",E10>IFERROR(VLOOKUP(A10,ラック定義!$A:$B,2,FALSE),47)),"／総Uをはみ出す","")&IF(AND(A10<>"",COUNTIF(ラック定義!$A:$A,A10)=0),"／ラックが定義にない","")&IF(AND(SUMPRODUCT((機器台帳!$A$2:$A$400=$A10)*((機器台帳!$B$2:$B$400=$B10)+(機器台帳!$B$2:$B$400="両面")+($B10="両面")>0)*(機器台帳!$C$2:$C$400<=$C10+$D10-1)*(機器台帳!$C$2:$C$400+機器台帳!$D$2:$D$400-1>=$C10)*(機器台帳!$F$2:$F$400<>""))-1>0,NOT(SUMPRODUCT(--ISNUMBER(SEARCH({"棚板","棚","アングル","ｱﾝｸﾞﾙ","使用不可","ケーブル","ｹｰﾌﾞﾙ","PatchPnael","パッチ","引き出し","引出","ブランク","ﾌﾞﾗﾝｸ","マネージ","ﾏﾈｰｼﾞ","PDU","ONU"},$F10&"")))>0)),"／同じUに他の機器(横並びなら正常)","")&IF(AND(M10<>"",COUNTIFS(回路定義!$A:$A,A10,回路定義!$B:$B,M10)=0),"／回路1が定義にない","")&IF(AND(P10<>"",COUNTIFS(回路定義!$A:$A,A10,回路定義!$B:$B,P10)=0),"／回路2が定義にない","")&IF(AND(S10<>"",COUNTIFS(回路定義!$A:$A,A10,回路定義!$B:$B,S10)=0),"／回路3が定義にない",""))="","",MID(IF(AND(Y10=0,NOT(SUMPRODUCT(--ISNUMBER(SEARCH({"棚板","棚","アングル","ｱﾝｸﾞﾙ","使用不可","ケーブル","ｹｰﾌﾞﾙ","PatchPnael","パッチ","引き出し","引出","ブランク","ﾌﾞﾗﾝｸ","マネージ","ﾏﾈｰｼﾞ","PDU","ONU"},$F10&"")))>0),NOT(SUMPRODUCT(--ISNUMBER(SEARCH({"電源オフ","未投入","停止","未使用","撤去"},$X10&"")))>0)),"／電力が未記入","")&IF(AND(NOT(ISNUMBER(J10)),NOT(SUMPRODUCT(--ISNUMBER(SEARCH({"棚板","棚","アングル","ｱﾝｸﾞﾙ","使用不可","ケーブル","ｹｰﾌﾞﾙ","PatchPnael","パッチ","引き出し","引出","ブランク","ﾌﾞﾗﾝｸ","マネージ","ﾏﾈｰｼﾞ","PDU","ONU"},$F10&"")))>0)),"／重量が未記入","")&IF(AND(K10<>"",NOT(ISNUMBER(K10))),"／電圧が数値でない","")&IF(AND(N10<>"",NOT(ISNUMBER(N10))),"／電流が数値でない","")&IF(AND(C10<>"",C10<1),"／開始Uが1未満","")&IF(AND(E10<>"",E10>IFERROR(VLOOKUP(A10,ラック定義!$A:$B,2,FALSE),47)),"／総Uをはみ出す","")&IF(AND(A10<>"",COUNTIF(ラック定義!$A:$A,A10)=0),"／ラックが定義にない","")&IF(AND(SUMPRODUCT((機器台帳!$A$2:$A$400=$A10)*((機器台帳!$B$2:$B$400=$B10)+(機器台帳!$B$2:$B$400="両面")+($B10="両面")>0)*(機器台帳!$C$2:$C$400<=$C10+$D10-1)*(機器台帳!$C$2:$C$400+機器台帳!$D$2:$D$400-1>=$C10)*(機器台帳!$F$2:$F$400<>""))-1>0,NOT(SUMPRODUCT(--ISNUMBER(SEARCH({"棚板","棚","アングル","ｱﾝｸﾞﾙ","使用不可","ケーブル","ｹｰﾌﾞﾙ","PatchPnael","パッチ","引き出し","引出","ブランク","ﾌﾞﾗﾝｸ","マネージ","ﾏﾈｰｼﾞ","PDU","ONU"},$F10&"")))>0)),"／同じUに他の機器(横並びなら正常)","")&IF(AND(M10<>"",COUNTIFS(回路定義!$A:$A,A10,回路定義!$B:$B,M10)=0),"／回路1が定義にない","")&IF(AND(P10<>"",COUNTIFS(回路定義!$A:$A,A10,回路定義!$B:$B,P10)=0),"／回路2が定義にない","")&IF(AND(S10<>"",COUNTIFS(回路定義!$A:$A,A10,回路定義!$B:$B,S10)=0),"／回路3が定義にない",""),2,300)))
A11: E24-S8-1 | B11: 両面 | C11: 13 | D11: 2 | E11: =IF(C11="","",C11+D11-1) | F11: Unity XT 480F | G11: H1908439 | I11: Storage | J11: 20 | K11: 100 | L11: 2 | M11: 100V 20A （1） | N11: 2 | O11: 1 | P11: 100V 20A （2） | Q11: 2 | R11: 1 | Y11: =COUNT(N11,Q11,T11) | Z11: =IF(OR(K11="",NOT(ISNUMBER(K11))),"",K11*SUM(N11,Q11,T11)) | AA11: =IF(OR(Y11=0,N11=""),"",N11/Y11) | AB11: =IF(OR(Y11=0,Q11=""),"",Q11/Y11) | AC11: =IF(OR(Y11=0,T11=""),"",T11/Y11) | AD11: =IF(F11="","",IF((IF(AND(Y11=0,NOT(SUMPRODUCT(--ISNUMBER(SEARCH({"棚板","棚","アングル","ｱﾝｸﾞﾙ","使用不可","ケーブル","ｹｰﾌﾞﾙ","PatchPnael","パッチ","引き出し","引出","ブランク","ﾌﾞﾗﾝｸ","マネージ","ﾏﾈｰｼﾞ","PDU","ONU"},$F11&"")))>0),NOT(SUMPRODUCT(--ISNUMBER(SEARCH({"電源オフ","未投入","停止","未使用","撤去"},$X11&"")))>0)),"／電力が未記入","")&IF(AND(NOT(ISNUMBER(J11)),NOT(SUMPRODUCT(--ISNUMBER(SEARCH({"棚板","棚","アングル","ｱﾝｸﾞﾙ","使用不可","ケーブル","ｹｰﾌﾞﾙ","PatchPnael","パッチ","引き出し","引出","ブランク","ﾌﾞﾗﾝｸ","マネージ","ﾏﾈｰｼﾞ","PDU","ONU"},$F11&"")))>0)),"／重量が未記入","")&IF(AND(K11<>"",NOT(ISNUMBER(K11))),"／電圧が数値でない","")&IF(AND(N11<>"",NOT(ISNUMBER(N11))),"／電流が数値でない","")&IF(AND(C11<>"",C11<1),"／開始Uが1未満","")&IF(AND(E11<>"",E11>IFERROR(VLOOKUP(A11,ラック定義!$A:$B,2,FALSE),47)),"／総Uをはみ出す","")&IF(AND(A11<>"",COUNTIF(ラック定義!$A:$A,A11)=0),"／ラックが定義にない","")&IF(AND(SUMPRODUCT((機器台帳!$A$2:$A$400=$A11)*((機器台帳!$B$2:$B$400=$B11)+(機器台帳!$B$2:$B$400="両面")+($B11="両面")>0)*(機器台帳!$C$2:$C$400<=$C11+$D11-1)*(機器台帳!$C$2:$C$400+機器台帳!$D$2:$D$400-1>=$C11)*(機器台帳!$F$2:$F$400<>""))-1>0,NOT(SUMPRODUCT(--ISNUMBER(SEARCH({"棚板","棚","アングル","ｱﾝｸﾞﾙ","使用不可","ケーブル","ｹｰﾌﾞﾙ","PatchPnael","パッチ","引き出し","引出","ブランク","ﾌﾞﾗﾝｸ","マネージ","ﾏﾈｰｼﾞ","PDU","ONU"},$F11&"")))>0)),"／同じUに他の機器(横並びなら正常)","")&IF(AND(M11<>"",COUNTIFS(回路定義!$A:$A,A11,回路定義!$B:$B,M11)=0),"／回路1が定義にない","")&IF(AND(P11<>"",COUNTIFS(回路定義!$A:$A,A11,回路定義!$B:$B,P11)=0),"／回路2が定義にない","")&IF(AND(S11<>"",COUNTIFS(回路定義!$A:$A,A11,回路定義!$B:$B,S11)=0),"／回路3が定義にない",""))="","",MID(IF(AND(Y11=0,NOT(SUMPRODUCT(--ISNUMBER(SEARCH({"棚板","棚","アングル","ｱﾝｸﾞﾙ","使用不可","ケーブル","ｹｰﾌﾞﾙ","PatchPnael","パッチ","引き出し","引出","ブランク","ﾌﾞﾗﾝｸ","マネージ","ﾏﾈｰｼﾞ","PDU","ONU"},$F11&"")))>0),NOT(SUMPRODUCT(--ISNUMBER(SEARCH({"電源オフ","未投入","停止","未使用","撤去"},$X11&"")))>0)),"／電力が未記入","")&IF(AND(NOT(ISNUMBER(J11)),NOT(SUMPRODUCT(--ISNUMBER(SEARCH({"棚板","棚","アングル","ｱﾝｸﾞﾙ","使用不可","ケーブル","ｹｰﾌﾞﾙ","PatchPnael","パッチ","引き出し","引出","ブランク","ﾌﾞﾗﾝｸ","マネージ","ﾏﾈｰｼﾞ","PDU","ONU"},$F11&"")))>0)),"／重量が未記入","")&IF(AND(K11<>"",NOT(ISNUMBER(K11))),"／電圧が数値でない","")&IF(AND(N11<>"",NOT(ISNUMBER(N11))),"／電流が数値でない","")&IF(AND(C11<>"",C11<1),"／開始Uが1未満","")&IF(AND(E11<>"",E11>IFERROR(VLOOKUP(A11,ラック定義!$A:$B,2,FALSE),47)),"／総Uをはみ出す","")&IF(AND(A11<>"",COUNTIF(ラック定義!$A:$A,A11)=0),"／ラックが定義にない","")&IF(AND(SUMPRODUCT((機器台帳!$A$2:$A$400=$A11)*((機器台帳!$B$2:$B$400=$B11)+(機器台帳!$B$2:$B$400="両面")+($B11="両面")>0)*(機器台帳!$C$2:$C$400<=$C11+$D11-1)*(機器台帳!$C$2:$C$400+機器台帳!$D$2:$D$400-1>=$C11)*(機器台帳!$F$2:$F$400<>""))-1>0,NOT(SUMPRODUCT(--ISNUMBER(SEARCH({"棚板","棚","アングル","ｱﾝｸﾞﾙ","使用不可","ケーブル","ｹｰﾌﾞﾙ","PatchPnael","パッチ","引き出し","引出","ブランク","ﾌﾞﾗﾝｸ","マネージ","ﾏﾈｰｼﾞ","PDU","ONU"},$F11&"")))>0)),"／同じUに他の機器(横並びなら正常)","")&IF(AND(M11<>"",COUNTIFS(回路定義!$A:$A,A11,回路定義!$B:$B,M11)=0),"／回路1が定義にない","")&IF(AND(P11<>"",COUNTIFS(回路定義!$A:$A,A11,回路定義!$B:$B,P11)=0),"／回路2が定義にない","")&IF(AND(S11<>"",COUNTIFS(回路定義!$A:$A,A11,回路定義!$B:$B,S11)=0),"／回路3が定義にない",""),2,300)))
A12: E24-S8-1 | B12: 両面 | C12: 11 | D12: 1 | E12: =IF(C12="","",C12+D12-1) | F12: Unity XT 480F | G12: H1911730 | I12: Storage | J12: 20 | K12: 200 | L12: 2 | M12: 200V 30A （1） | N12: 2 | O12: 2 | Y12: =COUNT(N12,Q12,T12) | Z12: =IF(OR(K12="",NOT(ISNUMBER(K12))),"",K12*SUM(N12,Q12,T12)) | AA12: =IF(OR(Y12=0,N12=""),"",N12/Y12) | AB12: =IF(OR(Y12=0,Q12=""),"",Q12/Y12) | AC12: =IF(OR(Y12=0,T12=""),"",T12/Y12) | AD12: =IF(F12="","",IF((IF(AND(Y12=0,NOT(SUMPRODUCT(--ISNUMBER(SEARCH({"棚板","棚","アングル","ｱﾝｸﾞﾙ","使用不可","ケーブル","ｹｰﾌﾞﾙ","PatchPnael","パッチ","引き出し","引出","ブランク","ﾌﾞﾗﾝｸ","マネージ","ﾏﾈｰｼﾞ","PDU","ONU"},$F12&"")))>0),NOT(SUMPRODUCT(--ISNUMBER(SEARCH({"電源オフ","未投入","停止","未使用","撤去"},$X12&"")))>0)),"／電力が未記入","")&IF(AND(NOT(ISNUMBER(J12)),NOT(SUMPRODUCT(--ISNUMBER(SEARCH({"棚板","棚","アングル","ｱﾝｸﾞﾙ","使用不可","ケーブル","ｹｰﾌﾞﾙ","PatchPnael","パッチ","引き出し","引出","ブランク","ﾌﾞﾗﾝｸ","マネージ","ﾏﾈｰｼﾞ","PDU","ONU"},$F12&"")))>0)),"／重量が未記入","")&IF(AND(K12<>"",NOT(ISNUMBER(K12))),"／電圧が数値でない","")&IF(AND(N12<>"",NOT(ISNUMBER(N12))),"／電流が数値でない","")&IF(AND(C12<>"",C12<1),"／開始Uが1未満","")&IF(AND(E12<>"",E12>IFERROR(VLOOKUP(A12,ラック定義!$A:$B,2,FALSE),47)),"／総Uをはみ出す","")&IF(AND(A12<>"",COUNTIF(ラック定義!$A:$A,A12)=0),"／ラックが定義にない","")&IF(AND(SUMPRODUCT((機器台帳!$A$2:$A$400=$A12)*((機器台帳!$B$2:$B$400=$B12)+(機器台帳!$B$2:$B$400="両面")+($B12="両面")>0)*(機器台帳!$C$2:$C$400<=$C12+$D12-1)*(機器台帳!$C$2:$C$400+機器台帳!$D$2:$D$400-1>=$C12)*(機器台帳!$F$2:$F$400<>""))-1>0,NOT(SUMPRODUCT(--ISNUMBER(SEARCH({"棚板","棚","アングル","ｱﾝｸﾞﾙ","使用不可","ケーブル","ｹｰﾌﾞﾙ","PatchPnael","パッチ","引き出し","引出","ブランク","ﾌﾞﾗﾝｸ","マネージ","ﾏﾈｰｼﾞ","PDU","ONU"},$F12&"")))>0)),"／同じUに他の機器(横並びなら正常)","")&IF(AND(M12<>"",COUNTIFS(回路定義!$A:$A,A12,回路定義!$B:$B,M12)=0),"／回路1が定義にない","")&IF(AND(P12<>"",COUNTIFS(回路定義!$A:$A,A12,回路定義!$B:$B,P12)=0),"／回路2が定義にない","")&IF(AND(S12<>"",COUNTIFS(回路定義!$A:$A,A12,回路定義!$B:$B,S12)=0),"／回路3が定義にない",""))="","",MID(IF(AND(Y12=0,NOT(SUMPRODUCT(--ISNUMBER(SEARCH({"棚板","棚","アングル","ｱﾝｸﾞﾙ","使用不可","ケーブル","ｹｰﾌﾞﾙ","PatchPnael","パッチ","引き出し","引出","ブランク","ﾌﾞﾗﾝｸ","マネージ","ﾏﾈｰｼﾞ","PDU","ONU"},$F12&"")))>0),NOT(SUMPRODUCT(--ISNUMBER(SEARCH({"電源オフ","未投入","停止","未使用","撤去"},$X12&"")))>0)),"／電力が未記入","")&IF(AND(NOT(ISNUMBER(J12)),NOT(SUMPRODUCT(--ISNUMBER(SEARCH({"棚板","棚","アングル","ｱﾝｸﾞﾙ","使用不可","ケーブル","ｹｰﾌﾞﾙ","PatchPnael","パッチ","引き出し","引出","ブランク","ﾌﾞﾗﾝｸ","マネージ","ﾏﾈｰｼﾞ","PDU","ONU"},$F12&"")))>0)),"／重量が未記入","")&IF(AND(K12<>"",NOT(ISNUMBER(K12))),"／電圧が数値でない","")&IF(AND(N12<>"",NOT(ISNUMBER(N12))),"／電流が数値でない","")&IF(AND(C12<>"",C12<1),"／開始Uが1未満","")&IF(AND(E12<>"",E12>IFERROR(VLOOKUP(A12,ラック定義!$A:$B,2,FALSE),47)),"／総Uをはみ出す","")&IF(AND(A12<>"",COUNTIF(ラック定義!$A:$A,A12)=0),"／ラックが定義にない","")&IF(AND(SUMPRODUCT((機器台帳!$A$2:$A$400=$A12)*((機器台帳!$B$2:$B$400=$B12)+(機器台帳!$B$2:$B$400="両面")+($B12="両面")>0)*(機器台帳!$C$2:$C$400<=$C12+$D12-1)*(機器台帳!$C$2:$C$400+機器台帳!$D$2:$D$400-1>=$C12)*(機器台帳!$F$2:$F$400<>""))-1>0,NOT(SUMPRODUCT(--ISNUMBER(SEARCH({"棚板","棚","アングル","ｱﾝｸﾞﾙ","使用不可","ケーブル","ｹｰﾌﾞﾙ","PatchPnael","パッチ","引き出し","引出","ブランク","ﾌﾞﾗﾝｸ","マネージ","ﾏﾈｰｼﾞ","PDU","ONU"},$F12&"")))>0)),"／同じUに他の機器(横並びなら正常)","")&IF(AND(M12<>"",COUNTIFS(回路定義!$A:$A,A12,回路定義!$B:$B,M12)=0),"／回路1が定義にない","")&IF(AND(P12<>"",COUNTIFS(回路定義!$A:$A,A12,回路定義!$B:$B,P12)=0),"／回路2が定義にない","")&IF(AND(S12<>"",COUNTIFS(回路定義!$A:$A,A12,回路定義!$B:$B,S12)=0),"／回路3が定義にない",""),2,300)))
A13: E24-S8-1 | B13: 両面 | C13: 4 | D13: 2 | E13: =IF(C13="","",C13+D13-1) | F13: 200V Rack PDU | G13: H1918632 | I13: PDU | J13: 10 | V13: 前留 | X13: L6-30R * 1回路×1口 | Y13: =COUNT(N13,Q13,T13) | Z13: =IF(OR(K13="",NOT(ISNUMBER(K13))),"",K13*SUM(N13,Q13,T13)) | AA13: =IF(OR(Y13=0,N13=""),"",N13/Y13) | AB13: =IF(OR(Y13=0,Q13=""),"",Q13/Y13) | AC13: =IF(OR(Y13=0,T13=""),"",T13/Y13) | AD13: =IF(F13="","",IF((IF(AND(Y13=0,NOT(SUMPRODUCT(--ISNUMBER(SEARCH({"棚板","棚","アングル","ｱﾝｸﾞﾙ","使用不可","ケーブル","ｹｰﾌﾞﾙ","PatchPnael","パッチ","引き出し","引出","ブランク","ﾌﾞﾗﾝｸ","マネージ","ﾏﾈｰｼﾞ","PDU","ONU"},$F13&"")))>0),NOT(SUMPRODUCT(--ISNUMBER(SEARCH({"電源オフ","未投入","停止","未使用","撤去"},$X13&"")))>0)),"／電力が未記入","")&IF(AND(NOT(ISNUMBER(J13)),NOT(SUMPRODUCT(--ISNUMBER(SEARCH({"棚板","棚","アングル","ｱﾝｸﾞﾙ","使用不可","ケーブル","ｹｰﾌﾞﾙ","PatchPnael","パッチ","引き出し","引出","ブランク","ﾌﾞﾗﾝｸ","マネージ","ﾏﾈｰｼﾞ","PDU","ONU"},$F13&"")))>0)),"／重量が未記入","")&IF(AND(K13<>"",NOT(ISNUMBER(K13))),"／電圧が数値でない","")&IF(AND(N13<>"",NOT(ISNUMBER(N13))),"／電流が数値でない","")&IF(AND(C13<>"",C13<1),"／開始Uが1未満","")&IF(AND(E13<>"",E13>IFERROR(VLOOKUP(A13,ラック定義!$A:$B,2,FALSE),47)),"／総Uをはみ出す","")&IF(AND(A13<>"",COUNTIF(ラック定義!$A:$A,A13)=0),"／ラックが定義にない","")&IF(AND(SUMPRODUCT((機器台帳!$A$2:$A$400=$A13)*((機器台帳!$B$2:$B$400=$B13)+(機器台帳!$B$2:$B$400="両面")+($B13="両面")>0)*(機器台帳!$C$2:$C$400<=$C13+$D13-1)*(機器台帳!$C$2:$C$400+機器台帳!$D$2:$D$400-1>=$C13)*(機器台帳!$F$2:$F$400<>""))-1>0,NOT(SUMPRODUCT(--ISNUMBER(SEARCH({"棚板","棚","アングル","ｱﾝｸﾞﾙ","使用不可","ケーブル","ｹｰﾌﾞﾙ","PatchPnael","パッチ","引き出し","引出","ブランク","ﾌﾞﾗﾝｸ","マネージ","ﾏﾈｰｼﾞ","PDU","ONU"},$F13&"")))>0)),"／同じUに他の機器(横並びなら正常)","")&IF(AND(M13<>"",COUNTIFS(回路定義!$A:$A,A13,回路定義!$B:$B,M13)=0),"／回路1が定義にない","")&IF(AND(P13<>"",COUNTIFS(回路定義!$A:$A,A13,回路定義!$B:$B,P13)=0),"／回路2が定義にない","")&IF(AND(S13<>"",COUNTIFS(回路定義!$A:$A,A13,回路定義!$B:$B,S13)=0),"／回路3が定義にない",""))="","",MID(IF(AND(Y13=0,NOT(SUMPRODUCT(--ISNUMBER(SEARCH({"棚板","棚","アングル","ｱﾝｸﾞﾙ","使用不可","ケーブル","ｹｰﾌﾞﾙ","PatchPnael","パッチ","引き出し","引出","ブランク","ﾌﾞﾗﾝｸ","マネージ","ﾏﾈｰｼﾞ","PDU","ONU"},$F13&"")))>0),NOT(SUMPRODUCT(--ISNUMBER(SEARCH({"電源オフ","未投入","停止","未使用","撤去"},$X13&"")))>0)),"／電力が未記入","")&IF(AND(NOT(ISNUMBER(J13)),NOT(SUMPRODUCT(--ISNUMBER(SEARCH({"棚板","棚","アングル","ｱﾝｸﾞﾙ","使用不可","ケーブル","ｹｰﾌﾞﾙ","PatchPnael","パッチ","引き出し","引出","ブランク","ﾌﾞﾗﾝｸ","マネージ","ﾏﾈｰｼﾞ","PDU","ONU"},$F13&"")))>0)),"／重量が未記入","")&IF(AND(K13<>"",NOT(ISNUMBER(K13))),"／電圧が数値でない","")&IF(AND(N13<>"",NOT(ISNUMBER(N13))),"／電流が数値でない","")&IF(AND(C13<>"",C13<1),"／開始Uが1未満","")&IF(AND(E13<>"",E13>IFERROR(VLOOKUP(A13,ラック定義!$A:$B,2,FALSE),47)),"／総Uをはみ出す","")&IF(AND(A13<>"",COUNTIF(ラック定義!$A:$A,A13)=0),"／ラックが定義にない","")&IF(AND(SUMPRODUCT((機器台帳!$A$2:$A$400=$A13)*((機器台帳!$B$2:$B$400=$B13)+(機器台帳!$B$2:$B$400="両面")+($B13="両面")>0)*(機器台帳!$C$2:$C$400<=$C13+$D13-1)*(機器台帳!$C$2:$C$400+機器台帳!$D$2:$D$400-1>=$C13)*(機器台帳!$F$2:$F$400<>""))-1>0,NOT(SUMPRODUCT(--ISNUMBER(SEARCH({"棚板","棚","アングル","ｱﾝｸﾞﾙ","使用不可","ケーブル","ｹｰﾌﾞﾙ","PatchPnael","パッチ","引き出し","引出","ブランク","ﾌﾞﾗﾝｸ","マネージ","ﾏﾈｰｼﾞ","PDU","ONU"},$F13&"")))>0)),"／同じUに他の機器(横並びなら正常)","")&IF(AND(M13<>"",COUNTIFS(回路定義!$A:$A,A13,回路定義!$B:$B,M13)=0),"／回路1が定義にない","")&IF(AND(P13<>"",COUNTIFS(回路定義!$A:$A,A13,回路定義!$B:$B,P13)=0),"／回路2が定義にない","")&IF(AND(S13<>"",COUNTIFS(回路定義!$A:$A,A13,回路定義!$B:$B,S13)=0),"／回路3が定義にない",""),2,300)))
A14: E24-S8-1 | B14: 両面 | C14: 1 | D14: 3 | E14: =IF(C14="","",C14+D14-1) | F14: 使用不可 | Y14: =COUNT(N14,Q14,T14) | Z14: =IF(OR(K14="",NOT(ISNUMBER(K14))),"",K14*SUM(N14,Q14,T14)) | AA14: =IF(OR(Y14=0,N14=""),"",N14/Y14) | AB14: =IF(OR(Y14=0,Q14=""),"",Q14/Y14) | AC14: =IF(OR(Y14=0,T14=""),"",T14/Y14) | AD14: =IF(F14="","",IF((IF(AND(Y14=0,NOT(SUMPRODUCT(--ISNUMBER(SEARCH({"棚板","棚","アングル","ｱﾝｸﾞﾙ","使用不可","ケーブル","ｹｰﾌﾞﾙ","PatchPnael","パッチ","引き出し","引出","ブランク","ﾌﾞﾗﾝｸ","マネージ","ﾏﾈｰｼﾞ","PDU","ONU"},$F14&"")))>0),NOT(SUMPRODUCT(--ISNUMBER(SEARCH({"電源オフ","未投入","停止","未使用","撤去"},$X14&"")))>0)),"／電力が未記入","")&IF(AND(NOT(ISNUMBER(J14)),NOT(SUMPRODUCT(--ISNUMBER(SEARCH({"棚板","棚","アングル","ｱﾝｸﾞﾙ","使用不可","ケーブル","ｹｰﾌﾞﾙ","PatchPnael","パッチ","引き出し","引出","ブランク","ﾌﾞﾗﾝｸ","マネージ","ﾏﾈｰｼﾞ","PDU","ONU"},$F14&"")))>0)),"／重量が未記入","")&IF(AND(K14<>"",NOT(ISNUMBER(K14))),"／電圧が数値でない","")&IF(AND(N14<>"",NOT(ISNUMBER(N14))),"／電流が数値でない","")&IF(AND(C14<>"",C14<1),"／開始Uが1未満","")&IF(AND(E14<>"",E14>IFERROR(VLOOKUP(A14,ラック定義!$A:$B,2,FALSE),47)),"／総Uをはみ出す","")&IF(AND(A14<>"",COUNTIF(ラック定義!$A:$A,A14)=0),"／ラックが定義にない","")&IF(AND(SUMPRODUCT((機器台帳!$A$2:$A$400=$A14)*((機器台帳!$B$2:$B$400=$B14)+(機器台帳!$B$2:$B$400="両面")+($B14="両面")>0)*(機器台帳!$C$2:$C$400<=$C14+$D14-1)*(機器台帳!$C$2:$C$400+機器台帳!$D$2:$D$400-1>=$C14)*(機器台帳!$F$2:$F$400<>""))-1>0,NOT(SUMPRODUCT(--ISNUMBER(SEARCH({"棚板","棚","アングル","ｱﾝｸﾞﾙ","使用不可","ケーブル","ｹｰﾌﾞﾙ","PatchPnael","パッチ","引き出し","引出","ブランク","ﾌﾞﾗﾝｸ","マネージ","ﾏﾈｰｼﾞ","PDU","ONU"},$F14&"")))>0)),"／同じUに他の機器(横並びなら正常)","")&IF(AND(M14<>"",COUNTIFS(回路定義!$A:$A,A14,回路定義!$B:$B,M14)=0),"／回路1が定義にない","")&IF(AND(P14<>"",COUNTIFS(回路定義!$A:$A,A14,回路定義!$B:$B,P14)=0),"／回路2が定義にない","")&IF(AND(S14<>"",COUNTIFS(回路定義!$A:$A,A14,回路定義!$B:$B,S14)=0),"／回路3が定義にない",""))="","",MID(IF(AND(Y14=0,NOT(SUMPRODUCT(--ISNUMBER(SEARCH({"棚板","棚","アングル","ｱﾝｸﾞﾙ","使用不可","ケーブル","ｹｰﾌﾞﾙ","PatchPnael","パッチ","引き出し","引出","ブランク","ﾌﾞﾗﾝｸ","マネージ","ﾏﾈｰｼﾞ","PDU","ONU"},$F14&"")))>0),NOT(SUMPRODUCT(--ISNUMBER(SEARCH({"電源オフ","未投入","停止","未使用","撤去"},$X14&"")))>0)),"／電力が未記入","")&IF(AND(NOT(ISNUMBER(J14)),NOT(SUMPRODUCT(--ISNUMBER(SEARCH({"棚板","棚","アングル","ｱﾝｸﾞﾙ","使用不可","ケーブル","ｹｰﾌﾞﾙ","PatchPnael","パッチ","引き出し","引出","ブランク","ﾌﾞﾗﾝｸ","マネージ","ﾏﾈｰｼﾞ","PDU","ONU"},$F14&"")))>0)),"／重量が未記入","")&IF(AND(K14<>"",NOT(ISNUMBER(K14))),"／電圧が数値でない","")&IF(AND(N14<>"",NOT(ISNUMBER(N14))),"／電流が数値でない","")&IF(AND(C14<>"",C14<1),"／開始Uが1未満","")&IF(AND(E14<>"",E14>IFERROR(VLOOKUP(A14,ラック定義!$A:$B,2,FALSE),47)),"／総Uをはみ出す","")&IF(AND(A14<>"",COUNTIF(ラック定義!$A:$A,A14)=0),"／ラックが定義にない","")&IF(AND(SUMPRODUCT((機器台帳!$A$2:$A$400=$A14)*((機器台帳!$B$2:$B$400=$B14)+(機器台帳!$B$2:$B$400="両面")+($B14="両面")>0)*(機器台帳!$C$2:$C$400<=$C14+$D14-1)*(機器台帳!$C$2:$C$400+機器台帳!$D$2:$D$400-1>=$C14)*(機器台帳!$F$2:$F$400<>""))-1>0,NOT(SUMPRODUCT(--ISNUMBER(SEARCH({"棚板","棚","アングル","ｱﾝｸﾞﾙ","使用不可","ケーブル","ｹｰﾌﾞﾙ","PatchPnael","パッチ","引き出し","引出","ブランク","ﾌﾞﾗﾝｸ","マネージ","ﾏﾈｰｼﾞ","PDU","ONU"},$F14&"")))>0)),"／同じUに他の機器(横並びなら正常)","")&IF(AND(M14<>"",COUNTIFS(回路定義!$A:$A,A14,回路定義!$B:$B,M14)=0),"／回路1が定義にない","")&IF(AND(P14<>"",COUNTIFS(回路定義!$A:$A,A14,回路定義!$B:$B,P14)=0),"／回路2が定義にない","")&IF(AND(S14<>"",COUNTIFS(回路定義!$A:$A,A14,回路定義!$B:$B,S14)=0),"／回路3が定義にない",""),2,300)))
A15: E24-S8-1 | B15: 背面 | C15: 47 | D15: 1 | E15: =IF(C15="","",C15+D15-1) | F15: ｹｰﾌﾞﾙﾏﾈｰｼﾞﾒﾝﾄ（背面） | Y15: =COUNT(N15,Q15,T15) | Z15: =IF(OR(K15="",NOT(ISNUMBER(K15))),"",K15*SUM(N15,Q15,T15)) | AA15: =IF(OR(Y15=0,N15=""),"",N15/Y15) | AB15: =IF(OR(Y15=0,Q15=""),"",Q15/Y15) | AC15: =IF(OR(Y15=0,T15=""),"",T15/Y15) | AD15: =IF(F15="","",IF((IF(AND(Y15=0,NOT(SUMPRODUCT(--ISNUMBER(SEARCH({"棚板","棚","アングル","ｱﾝｸﾞﾙ","使用不可","ケーブル","ｹｰﾌﾞﾙ","PatchPnael","パッチ","引き出し","引出","ブランク","ﾌﾞﾗﾝｸ","マネージ","ﾏﾈｰｼﾞ","PDU","ONU"},$F15&"")))>0),NOT(SUMPRODUCT(--ISNUMBER(SEARCH({"電源オフ","未投入","停止","未使用","撤去"},$X15&"")))>0)),"／電力が未記入","")&IF(AND(NOT(ISNUMBER(J15)),NOT(SUMPRODUCT(--ISNUMBER(SEARCH({"棚板","棚","アングル","ｱﾝｸﾞﾙ","使用不可","ケーブル","ｹｰﾌﾞﾙ","PatchPnael","パッチ","引き出し","引出","ブランク","ﾌﾞﾗﾝｸ","マネージ","ﾏﾈｰｼﾞ","PDU","ONU"},$F15&"")))>0)),"／重量が未記入","")&IF(AND(K15<>"",NOT(ISNUMBER(K15))),"／電圧が数値でない","")&IF(AND(N15<>"",NOT(ISNUMBER(N15))),"／電流が数値でない","")&IF(AND(C15<>"",C15<1),"／開始Uが1未満","")&IF(AND(E15<>"",E15>IFERROR(VLOOKUP(A15,ラック定義!$A:$B,2,FALSE),47)),"／総Uをはみ出す","")&IF(AND(A15<>"",COUNTIF(ラック定義!$A:$A,A15)=0),"／ラックが定義にない","")&IF(AND(SUMPRODUCT((機器台帳!$A$2:$A$400=$A15)*((機器台帳!$B$2:$B$400=$B15)+(機器台帳!$B$2:$B$400="両面")+($B15="両面")>0)*(機器台帳!$C$2:$C$400<=$C15+$D15-1)*(機器台帳!$C$2:$C$400+機器台帳!$D$2:$D$400-1>=$C15)*(機器台帳!$F$2:$F$400<>""))-1>0,NOT(SUMPRODUCT(--ISNUMBER(SEARCH({"棚板","棚","アングル","ｱﾝｸﾞﾙ","使用不可","ケーブル","ｹｰﾌﾞﾙ","PatchPnael","パッチ","引き出し","引出","ブランク","ﾌﾞﾗﾝｸ","マネージ","ﾏﾈｰｼﾞ","PDU","ONU"},$F15&"")))>0)),"／同じUに他の機器(横並びなら正常)","")&IF(AND(M15<>"",COUNTIFS(回路定義!$A:$A,A15,回路定義!$B:$B,M15)=0),"／回路1が定義にない","")&IF(AND(P15<>"",COUNTIFS(回路定義!$A:$A,A15,回路定義!$B:$B,P15)=0),"／回路2が定義にない","")&IF(AND(S15<>"",COUNTIFS(回路定義!$A:$A,A15,回路定義!$B:$B,S15)=0),"／回路3が定義にない",""))="","",MID(IF(AND(Y15=0,NOT(SUMPRODUCT(--ISNUMBER(SEARCH({"棚板","棚","アングル","ｱﾝｸﾞﾙ","使用不可","ケーブル","ｹｰﾌﾞﾙ","PatchPnael","パッチ","引き出し","引出","ブランク","ﾌﾞﾗﾝｸ","マネージ","ﾏﾈｰｼﾞ","PDU","ONU"},$F15&"")))>0),NOT(SUMPRODUCT(--ISNUMBER(SEARCH({"電源オフ","未投入","停止","未使用","撤去"},$X15&"")))>0)),"／電力が未記入","")&IF(AND(NOT(ISNUMBER(J15)),NOT(SUMPRODUCT(--ISNUMBER(SEARCH({"棚板","棚","アングル","ｱﾝｸﾞﾙ","使用不可","ケーブル","ｹｰﾌﾞﾙ","PatchPnael","パッチ","引き出し","引出","ブランク","ﾌﾞﾗﾝｸ","マネージ","ﾏﾈｰｼﾞ","PDU","ONU"},$F15&"")))>0)),"／重量が未記入","")&IF(AND(K15<>"",NOT(ISNUMBER(K15))),"／電圧が数値でない","")&IF(AND(N15<>"",NOT(ISNUMBER(N15))),"／電流が数値でない","")&IF(AND(C15<>"",C15<1),"／開始Uが1未満","")&IF(AND(E15<>"",E15>IFERROR(VLOOKUP(A15,ラック定義!$A:$B,2,FALSE),47)),"／総Uをはみ出す","")&IF(AND(A15<>"",COUNTIF(ラック定義!$A:$A,A15)=0),"／ラックが定義にない","")&IF(AND(SUMPRODUCT((機器台帳!$A$2:$A$400=$A15)*((機器台帳!$B$2:$B$400=$B15)+(機器台帳!$B$2:$B$400="両面")+($B15="両面")>0)*(機器台帳!$C$2:$C$400<=$C15+$D15-1)*(機器台帳!$C$2:$C$400+機器台帳!$D$2:$D$400-1>=$C15)*(機器台帳!$F$2:$F$400<>""))-1>0,NOT(SUMPRODUCT(--ISNUMBER(SEARCH({"棚板","棚","アングル","ｱﾝｸﾞﾙ","使用不可","ケーブル","ｹｰﾌﾞﾙ","PatchPnael","パッチ","引き出し","引出","ブランク","ﾌﾞﾗﾝｸ","マネージ","ﾏﾈｰｼﾞ","PDU","ONU"},$F15&"")))>0)),"／同じUに他の機器(横並びなら正常)","")&IF(AND(M15<>"",COUNTIFS(回路定義!$A:$A,A15,回路定義!$B:$B,M15)=0),"／回路1が定義にない","")&IF(AND(P15<>"",COUNTIFS(回路定義!$A:$A,A15,回路定義!$B:$B,P15)=0),"／回路2が定義にない","")&IF(AND(S15<>"",COUNTIFS(回路定義!$A:$A,A15,回路定義!$B:$B,S15)=0),"／回路3が定義にない",""),2,300)))
A16: E24-S8-1 | B16: 前面 | C16: 46 | D16: 1 | E16: =IF(C16="","",C16+D16-1) | F16: UTP 12port PatchPnael(前面) | Y16: =COUNT(N16,Q16,T16) | Z16: =IF(OR(K16="",NOT(ISNUMBER(K16))),"",K16*SUM(N16,Q16,T16)) | AA16: =IF(OR(Y16=0,N16=""),"",N16/Y16) | AB16: =IF(OR(Y16=0,Q16=""),"",Q16/Y16) | AC16: =IF(OR(Y16=0,T16=""),"",T16/Y16) | AD16: =IF(F16="","",IF((IF(AND(Y16=0,NOT(SUMPRODUCT(--ISNUMBER(SEARCH({"棚板","棚","アングル","ｱﾝｸﾞﾙ","使用不可","ケーブル","ｹｰﾌﾞﾙ","PatchPnael","パッチ","引き出し","引出","ブランク","ﾌﾞﾗﾝｸ","マネージ","ﾏﾈｰｼﾞ","PDU","ONU"},$F16&"")))>0),NOT(SUMPRODUCT(--ISNUMBER(SEARCH({"電源オフ","未投入","停止","未使用","撤去"},$X16&"")))>0)),"／電力が未記入","")&IF(AND(NOT(ISNUMBER(J16)),NOT(SUMPRODUCT(--ISNUMBER(SEARCH({"棚板","棚","アングル","ｱﾝｸﾞﾙ","使用不可","ケーブル","ｹｰﾌﾞﾙ","PatchPnael","パッチ","引き出し","引出","ブランク","ﾌﾞﾗﾝｸ","マネージ","ﾏﾈｰｼﾞ","PDU","ONU"},$F16&"")))>0)),"／重量が未記入","")&IF(AND(K16<>"",NOT(ISNUMBER(K16))),"／電圧が数値でない","")&IF(AND(N16<>"",NOT(ISNUMBER(N16))),"／電流が数値でない","")&IF(AND(C16<>"",C16<1),"／開始Uが1未満","")&IF(AND(E16<>"",E16>IFERROR(VLOOKUP(A16,ラック定義!$A:$B,2,FALSE),47)),"／総Uをはみ出す","")&IF(AND(A16<>"",COUNTIF(ラック定義!$A:$A,A16)=0),"／ラックが定義にない","")&IF(AND(SUMPRODUCT((機器台帳!$A$2:$A$400=$A16)*((機器台帳!$B$2:$B$400=$B16)+(機器台帳!$B$2:$B$400="両面")+($B16="両面")>0)*(機器台帳!$C$2:$C$400<=$C16+$D16-1)*(機器台帳!$C$2:$C$400+機器台帳!$D$2:$D$400-1>=$C16)*(機器台帳!$F$2:$F$400<>""))-1>0,NOT(SUMPRODUCT(--ISNUMBER(SEARCH({"棚板","棚","アングル","ｱﾝｸﾞﾙ","使用不可","ケーブル","ｹｰﾌﾞﾙ","PatchPnael","パッチ","引き出し","引出","ブランク","ﾌﾞﾗﾝｸ","マネージ","ﾏﾈｰｼﾞ","PDU","ONU"},$F16&"")))>0)),"／同じUに他の機器(横並びなら正常)","")&IF(AND(M16<>"",COUNTIFS(回路定義!$A:$A,A16,回路定義!$B:$B,M16)=0),"／回路1が定義にない","")&IF(AND(P16<>"",COUNTIFS(回路定義!$A:$A,A16,回路定義!$B:$B,P16)=0),"／回路2が定義にない","")&IF(AND(S16<>"",COUNTIFS(回路定義!$A:$A,A16,回路定義!$B:$B,S16)=0),"／回路3が定義にない",""))="","",MID(IF(AND(Y16=0,NOT(SUMPRODUCT(--ISNUMBER(SEARCH({"棚板","棚","アングル","ｱﾝｸﾞﾙ","使用不可","ケーブル","ｹｰﾌﾞﾙ","PatchPnael","パッチ","引き出し","引出","ブランク","ﾌﾞﾗﾝｸ","マネージ","ﾏﾈｰｼﾞ","PDU","ONU"},$F16&"")))>0),NOT(SUMPRODUCT(--ISNUMBER(SEARCH({"電源オフ","未投入","停止","未使用","撤去"},$X16&"")))>0)),"／電力が未記入","")&IF(AND(NOT(ISNUMBER(J16)),NOT(SUMPRODUCT(--ISNUMBER(SEARCH({"棚板","棚","アングル","ｱﾝｸﾞﾙ","使用不可","ケーブル","ｹｰﾌﾞﾙ","PatchPnael","パッチ","引き出し","引出","ブランク","ﾌﾞﾗﾝｸ","マネージ","ﾏﾈｰｼﾞ","PDU","ONU"},$F16&"")))>0)),"／重量が未記入","")&IF(AND(K16<>"",NOT(ISNUMBER(K16))),"／電圧が数値でない","")&IF(AND(N16<>"",NOT(ISNUMBER(N16))),"／電流が数値でない","")&IF(AND(C16<>"",C16<1),"／開始Uが1未満","")&IF(AND(E16<>"",E16>IFERROR(VLOOKUP(A16,ラック定義!$A:$B,2,FALSE),47)),"／総Uをはみ出す","")&IF(AND(A16<>"",COUNTIF(ラック定義!$A:$A,A16)=0),"／ラックが定義にない","")&IF(AND(SUMPRODUCT((機器台帳!$A$2:$A$400=$A16)*((機器台帳!$B$2:$B$400=$B16)+(機器台帳!$B$2:$B$400="両面")+($B16="両面")>0)*(機器台帳!$C$2:$C$400<=$C16+$D16-1)*(機器台帳!$C$2:$C$400+機器台帳!$D$2:$D$400-1>=$C16)*(機器台帳!$F$2:$F$400<>""))-1>0,NOT(SUMPRODUCT(--ISNUMBER(SEARCH({"棚板","棚","アングル","ｱﾝｸﾞﾙ","使用不可","ケーブル","ｹｰﾌﾞﾙ","PatchPnael","パッチ","引き出し","引出","ブランク","ﾌﾞﾗﾝｸ","マネージ","ﾏﾈｰｼﾞ","PDU","ONU"},$F16&"")))>0)),"／同じUに他の機器(横並びなら正常)","")&IF(AND(M16<>"",COUNTIFS(回路定義!$A:$A,A16,回路定義!$B:$B,M16)=0),"／回路1が定義にない","")&IF(AND(P16<>"",COUNTIFS(回路定義!$A:$A,A16,回路定義!$B:$B,P16)=0),"／回路2が定義にない","")&IF(AND(S16<>"",COUNTIFS(回路定義!$A:$A,A16,回路定義!$B:$B,S16)=0),"／回路3が定義にない",""),2,300)))
A17: E24-S8-1 | B17: 背面 | C17: 46 | D17: 1 | E17: =IF(C17="","",C17+D17-1) | F17: UTP 12port PatchPnael(背面) | Y17: =COUNT(N17,Q17,T17) | Z17: =IF(OR(K17="",NOT(ISNUMBER(K17))),"",K17*SUM(N17,Q17,T17)) | AA17: =IF(OR(Y17=0,N17=""),"",N17/Y17) | AB17: =IF(OR(Y17=0,Q17=""),"",Q17/Y17) | AC17: =IF(OR(Y17=0,T17=""),"",T17/Y17) | AD17: =IF(F17="","",IF((IF(AND(Y17=0,NOT(SUMPRODUCT(--ISNUMBER(SEARCH({"棚板","棚","アングル","ｱﾝｸﾞﾙ","使用不可","ケーブル","ｹｰﾌﾞﾙ","PatchPnael","パッチ","引き出し","引出","ブランク","ﾌﾞﾗﾝｸ","マネージ","ﾏﾈｰｼﾞ","PDU","ONU"},$F17&"")))>0),NOT(SUMPRODUCT(--ISNUMBER(SEARCH({"電源オフ","未投入","停止","未使用","撤去"},$X17&"")))>0)),"／電力が未記入","")&IF(AND(NOT(ISNUMBER(J17)),NOT(SUMPRODUCT(--ISNUMBER(SEARCH({"棚板","棚","アングル","ｱﾝｸﾞﾙ","使用不可","ケーブル","ｹｰﾌﾞﾙ","PatchPnael","パッチ","引き出し","引出","ブランク","ﾌﾞﾗﾝｸ","マネージ","ﾏﾈｰｼﾞ","PDU","ONU"},$F17&"")))>0)),"／重量が未記入","")&IF(AND(K17<>"",NOT(ISNUMBER(K17))),"／電圧が数値でない","")&IF(AND(N17<>"",NOT(ISNUMBER(N17))),"／電流が数値でない","")&IF(AND(C17<>"",C17<1),"／開始Uが1未満","")&IF(AND(E17<>"",E17>IFERROR(VLOOKUP(A17,ラック定義!$A:$B,2,FALSE),47)),"／総Uをはみ出す","")&IF(AND(A17<>"",COUNTIF(ラック定義!$A:$A,A17)=0),"／ラックが定義にない","")&IF(AND(SUMPRODUCT((機器台帳!$A$2:$A$400=$A17)*((機器台帳!$B$2:$B$400=$B17)+(機器台帳!$B$2:$B$400="両面")+($B17="両面")>0)*(機器台帳!$C$2:$C$400<=$C17+$D17-1)*(機器台帳!$C$2:$C$400+機器台帳!$D$2:$D$400-1>=$C17)*(機器台帳!$F$2:$F$400<>""))-1>0,NOT(SUMPRODUCT(--ISNUMBER(SEARCH({"棚板","棚","アングル","ｱﾝｸﾞﾙ","使用不可","ケーブル","ｹｰﾌﾞﾙ","PatchPnael","パッチ","引き出し","引出","ブランク","ﾌﾞﾗﾝｸ","マネージ","ﾏﾈｰｼﾞ","PDU","ONU"},$F17&"")))>0)),"／同じUに他の機器(横並びなら正常)","")&IF(AND(M17<>"",COUNTIFS(回路定義!$A:$A,A17,回路定義!$B:$B,M17)=0),"／回路1が定義にない","")&IF(AND(P17<>"",COUNTIFS(回路定義!$A:$A,A17,回路定義!$B:$B,P17)=0),"／回路2が定義にない","")&IF(AND(S17<>"",COUNTIFS(回路定義!$A:$A,A17,回路定義!$B:$B,S17)=0),"／回路3が定義にない",""))="","",MID(IF(AND(Y17=0,NOT(SUMPRODUCT(--ISNUMBER(SEARCH({"棚板","棚","アングル","ｱﾝｸﾞﾙ","使用不可","ケーブル","ｹｰﾌﾞﾙ","PatchPnael","パッチ","引き出し","引出","ブランク","ﾌﾞﾗﾝｸ","マネージ","ﾏﾈｰｼﾞ","PDU","ONU"},$F17&"")))>0),NOT(SUMPRODUCT(--ISNUMBER(SEARCH({"電源オフ","未投入","停止","未使用","撤去"},$X17&"")))>0)),"／電力が未記入","")&IF(AND(NOT(ISNUMBER(J17)),NOT(SUMPRODUCT(--ISNUMBER(SEARCH({"棚板","棚","アングル","ｱﾝｸﾞﾙ","使用不可","ケーブル","ｹｰﾌﾞﾙ","PatchPnael","パッチ","引き出し","引出","ブランク","ﾌﾞﾗﾝｸ","マネージ","ﾏﾈｰｼﾞ","PDU","ONU"},$F17&"")))>0)),"／重量が未記入","")&IF(AND(K17<>"",NOT(ISNUMBER(K17))),"／電圧が数値でない","")&IF(AND(N17<>"",NOT(ISNUMBER(N17))),"／電流が数値でない","")&IF(AND(C17<>"",C17<1),"／開始Uが1未満","")&IF(AND(E17<>"",E17>IFERROR(VLOOKUP(A17,ラック定義!$A:$B,2,FALSE),47)),"／総Uをはみ出す","")&IF(AND(A17<>"",COUNTIF(ラック定義!$A:$A,A17)=0),"／ラックが定義にない","")&IF(AND(SUMPRODUCT((機器台帳!$A$2:$A$400=$A17)*((機器台帳!$B$2:$B$400=$B17)+(機器台帳!$B$2:$B$400="両面")+($B17="両面")>0)*(機器台帳!$C$2:$C$400<=$C17+$D17-1)*(機器台帳!$C$2:$C$400+機器台帳!$D$2:$D$400-1>=$C17)*(機器台帳!$F$2:$F$400<>""))-1>0,NOT(SUMPRODUCT(--ISNUMBER(SEARCH({"棚板","棚","アングル","ｱﾝｸﾞﾙ","使用不可","ケーブル","ｹｰﾌﾞﾙ","PatchPnael","パッチ","引き出し","引出","ブランク","ﾌﾞﾗﾝｸ","マネージ","ﾏﾈｰｼﾞ","PDU","ONU"},$F17&"")))>0)),"／同じUに他の機器(横並びなら正常)","")&IF(AND(M17<>"",COUNTIFS(回路定義!$A:$A,A17,回路定義!$B:$B,M17)=0),"／回路1が定義にない","")&IF(AND(P17<>"",COUNTIFS(回路定義!$A:$A,A17,回路定義!$B:$B,P17)=0),"／回路2が定義にない","")&IF(AND(S17<>"",COUNTIFS(回路定義!$A:$A,A17,回路定義!$B:$B,S17)=0),"／回路3が定義にない",""),2,300)))
A18: E24-S8-1 | B18: 前面 | C18: 24 | D18: 1 | E18: =IF(C18="","",C18+D18-1) | F18: XC660 | G18: H2401558 | Y18: =COUNT(N18,Q18,T18) | Z18: =IF(OR(K18="",NOT(ISNUMBER(K18))),"",K18*SUM(N18,Q18,T18)) | AA18: =IF(OR(Y18=0,N18=""),"",N18/Y18) | AB18: =IF(OR(Y18=0,Q18=""),"",Q18/Y18) | AC18: =IF(OR(Y18=0,T18=""),"",T18/Y18) | AD18: =IF(F18="","",IF((IF(AND(Y18=0,NOT(SUMPRODUCT(--ISNUMBER(SEARCH({"棚板","棚","アングル","ｱﾝｸﾞﾙ","使用不可","ケーブル","ｹｰﾌﾞﾙ","PatchPnael","パッチ","引き出し","引出","ブランク","ﾌﾞﾗﾝｸ","マネージ","ﾏﾈｰｼﾞ","PDU","ONU"},$F18&"")))>0),NOT(SUMPRODUCT(--ISNUMBER(SEARCH({"電源オフ","未投入","停止","未使用","撤去"},$X18&"")))>0)),"／電力が未記入","")&IF(AND(NOT(ISNUMBER(J18)),NOT(SUMPRODUCT(--ISNUMBER(SEARCH({"棚板","棚","アングル","ｱﾝｸﾞﾙ","使用不可","ケーブル","ｹｰﾌﾞﾙ","PatchPnael","パッチ","引き出し","引出","ブランク","ﾌﾞﾗﾝｸ","マネージ","ﾏﾈｰｼﾞ","PDU","ONU"},$F18&"")))>0)),"／重量が未記入","")&IF(AND(K18<>"",NOT(ISNUMBER(K18))),"／電圧が数値でない","")&IF(AND(N18<>"",NOT(ISNUMBER(N18))),"／電流が数値でない","")&IF(AND(C18<>"",C18<1),"／開始Uが1未満","")&IF(AND(E18<>"",E18>IFERROR(VLOOKUP(A18,ラック定義!$A:$B,2,FALSE),47)),"／総Uをはみ出す","")&IF(AND(A18<>"",COUNTIF(ラック定義!$A:$A,A18)=0),"／ラックが定義にない","")&IF(AND(SUMPRODUCT((機器台帳!$A$2:$A$400=$A18)*((機器台帳!$B$2:$B$400=$B18)+(機器台帳!$B$2:$B$400="両面")+($B18="両面")>0)*(機器台帳!$C$2:$C$400<=$C18+$D18-1)*(機器台帳!$C$2:$C$400+機器台帳!$D$2:$D$400-1>=$C18)*(機器台帳!$F$2:$F$400<>""))-1>0,NOT(SUMPRODUCT(--ISNUMBER(SEARCH({"棚板","棚","アングル","ｱﾝｸﾞﾙ","使用不可","ケーブル","ｹｰﾌﾞﾙ","PatchPnael","パッチ","引き出し","引出","ブランク","ﾌﾞﾗﾝｸ","マネージ","ﾏﾈｰｼﾞ","PDU","ONU"},$F18&"")))>0)),"／同じUに他の機器(横並びなら正常)","")&IF(AND(M18<>"",COUNTIFS(回路定義!$A:$A,A18,回路定義!$B:$B,M18)=0),"／回路1が定義にない","")&IF(AND(P18<>"",COUNTIFS(回路定義!$A:$A,A18,回路定義!$B:$B,P18)=0),"／回路2が定義にない","")&IF(AND(S18<>"",COUNTIFS(回路定義!$A:$A,A18,回路定義!$B:$B,S18)=0),"／回路3が定義にない",""))="","",MID(IF(AND(Y18=0,NOT(SUMPRODUCT(--ISNUMBER(SEARCH({"棚板","棚","アングル","ｱﾝｸﾞﾙ","使用不可","ケーブル","ｹｰﾌﾞﾙ","PatchPnael","パッチ","引き出し","引出","ブランク","ﾌﾞﾗﾝｸ","マネージ","ﾏﾈｰｼﾞ","PDU","ONU"},$F18&"")))>0),NOT(SUMPRODUCT(--ISNUMBER(SEARCH({"電源オフ","未投入","停止","未使用","撤去"},$X18&"")))>0)),"／電力が未記入","")&IF(AND(NOT(ISNUMBER(J18)),NOT(SUMPRODUCT(--ISNUMBER(SEARCH({"棚板","棚","アングル","ｱﾝｸﾞﾙ","使用不可","ケーブル","ｹｰﾌﾞﾙ","PatchPnael","パッチ","引き出し","引出","ブランク","ﾌﾞﾗﾝｸ","マネージ","ﾏﾈｰｼﾞ","PDU","ONU"},$F18&"")))>0)),"／重量が未記入","")&IF(AND(K18<>"",NOT(ISNUMBER(K18))),"／電圧が数値でない","")&IF(AND(N18<>"",NOT(ISNUMBER(N18))),"／電流が数値でない","")&IF(AND(C18<>"",C18<1),"／開始Uが1未満","")&IF(AND(E18<>"",E18>IFERROR(VLOOKUP(A18,ラック定義!$A:$B,2,FALSE),47)),"／総Uをはみ出す","")&IF(AND(A18<>"",COUNTIF(ラック定義!$A:$A,A18)=0),"／ラックが定義にない","")&IF(AND(SUMPRODUCT((機器台帳!$A$2:$A$400=$A18)*((機器台帳!$B$2:$B$400=$B18)+(機器台帳!$B$2:$B$400="両面")+($B18="両面")>0)*(機器台帳!$C$2:$C$400<=$C18+$D18-1)*(機器台帳!$C$2:$C$400+機器台帳!$D$2:$D$400-1>=$C18)*(機器台帳!$F$2:$F$400<>""))-1>0,NOT(SUMPRODUCT(--ISNUMBER(SEARCH({"棚板","棚","アングル","ｱﾝｸﾞﾙ","使用不可","ケーブル","ｹｰﾌﾞﾙ","PatchPnael","パッチ","引き出し","引出","ブランク","ﾌﾞﾗﾝｸ","マネージ","ﾏﾈｰｼﾞ","PDU","ONU"},$F18&"")))>0)),"／同じUに他の機器(横並びなら正常)","")&IF(AND(M18<>"",COUNTIFS(回路定義!$A:$A,A18,回路定義!$B:$B,M18)=0),"／回路1が定義にない","")&IF(AND(P18<>"",COUNTIFS(回路定義!$A:$A,A18,回路定義!$B:$B,P18)=0),"／回路2が定義にない","")&IF(AND(S18<>"",COUNTIFS(回路定義!$A:$A,A18,回路定義!$B:$B,S18)=0),"／回路3が定義にない",""),2,300)))
A19: E24-S8-1 | B19: 前面 | C19: 22 | D19: 1 | E19: =IF(C19="","",C19+D19-1) | F19: XC660 | G19: H2401559 | Y19: =COUNT(N19,Q19,T19) | Z19: =IF(OR(K19="",NOT(ISNUMBER(K19))),"",K19*SUM(N19,Q19,T19)) | AA19: =IF(OR(Y19=0,N19=""),"",N19/Y19) | AB19: =IF(OR(Y19=0,Q19=""),"",Q19/Y19) | AC19: =IF(OR(Y19=0,T19=""),"",T19/Y19) | AD19: =IF(F19="","",IF((IF(AND(Y19=0,NOT(SUMPRODUCT(--ISNUMBER(SEARCH({"棚板","棚","アングル","ｱﾝｸﾞﾙ","使用不可","ケーブル","ｹｰﾌﾞﾙ","PatchPnael","パッチ","引き出し","引出","ブランク","ﾌﾞﾗﾝｸ","マネージ","ﾏﾈｰｼﾞ","PDU","ONU"},$F19&"")))>0),NOT(SUMPRODUCT(--ISNUMBER(SEARCH({"電源オフ","未投入","停止","未使用","撤去"},$X19&"")))>0)),"／電力が未記入","")&IF(AND(NOT(ISNUMBER(J19)),NOT(SUMPRODUCT(--ISNUMBER(SEARCH({"棚板","棚","アングル","ｱﾝｸﾞﾙ","使用不可","ケーブル","ｹｰﾌﾞﾙ","PatchPnael","パッチ","引き出し","引出","ブランク","ﾌﾞﾗﾝｸ","マネージ","ﾏﾈｰｼﾞ","PDU","ONU"},$F19&"")))>0)),"／重量が未記入","")&IF(AND(K19<>"",NOT(ISNUMBER(K19))),"／電圧が数値でない","")&IF(AND(N19<>"",NOT(ISNUMBER(N19))),"／電流が数値でない","")&IF(AND(C19<>"",C19<1),"／開始Uが1未満","")&IF(AND(E19<>"",E19>IFERROR(VLOOKUP(A19,ラック定義!$A:$B,2,FALSE),47)),"／総Uをはみ出す","")&IF(AND(A19<>"",COUNTIF(ラック定義!$A:$A,A19)=0),"／ラックが定義にない","")&IF(AND(SUMPRODUCT((機器台帳!$A$2:$A$400=$A19)*((機器台帳!$B$2:$B$400=$B19)+(機器台帳!$B$2:$B$400="両面")+($B19="両面")>0)*(機器台帳!$C$2:$C$400<=$C19+$D19-1)*(機器台帳!$C$2:$C$400+機器台帳!$D$2:$D$400-1>=$C19)*(機器台帳!$F$2:$F$400<>""))-1>0,NOT(SUMPRODUCT(--ISNUMBER(SEARCH({"棚板","棚","アングル","ｱﾝｸﾞﾙ","使用不可","ケーブル","ｹｰﾌﾞﾙ","PatchPnael","パッチ","引き出し","引出","ブランク","ﾌﾞﾗﾝｸ","マネージ","ﾏﾈｰｼﾞ","PDU","ONU"},$F19&"")))>0)),"／同じUに他の機器(横並びなら正常)","")&IF(AND(M19<>"",COUNTIFS(回路定義!$A:$A,A19,回路定義!$B:$B,M19)=0),"／回路1が定義にない","")&IF(AND(P19<>"",COUNTIFS(回路定義!$A:$A,A19,回路定義!$B:$B,P19)=0),"／回路2が定義にない","")&IF(AND(S19<>"",COUNTIFS(回路定義!$A:$A,A19,回路定義!$B:$B,S19)=0),"／回路3が定義にない",""))="","",MID(IF(AND(Y19=0,NOT(SUMPRODUCT(--ISNUMBER(SEARCH({"棚板","棚","アングル","ｱﾝｸﾞﾙ","使用不可","ケーブル","ｹｰﾌﾞﾙ","PatchPnael","パッチ","引き出し","引出","ブランク","ﾌﾞﾗﾝｸ","マネージ","ﾏﾈｰｼﾞ","PDU","ONU"},$F19&"")))>0),NOT(SUMPRODUCT(--ISNUMBER(SEARCH({"電源オフ","未投入","停止","未使用","撤去"},$X19&"")))>0)),"／電力が未記入","")&IF(AND(NOT(ISNUMBER(J19)),NOT(SUMPRODUCT(--ISNUMBER(SEARCH({"棚板","棚","アングル","ｱﾝｸﾞﾙ","使用不可","ケーブル","ｹｰﾌﾞﾙ","PatchPnael","パッチ","引き出し","引出","ブランク","ﾌﾞﾗﾝｸ","マネージ","ﾏﾈｰｼﾞ","PDU","ONU"},$F19&"")))>0)),"／重量が未記入","")&IF(AND(K19<>"",NOT(ISNUMBER(K19))),"／電圧が数値でない","")&IF(AND(N19<>"",NOT(ISNUMBER(N19))),"／電流が数値でない","")&IF(AND(C19<>"",C19<1),"／開始Uが1未満","")&IF(AND(E19<>"",E19>IFERROR(VLOOKUP(A19,ラック定義!$A:$B,2,FALSE),47)),"／総Uをはみ出す","")&IF(AND(A19<>"",COUNTIF(ラック定義!$A:$A,A19)=0),"／ラックが定義にない","")&IF(AND(SUMPRODUCT((機器台帳!$A$2:$A$400=$A19)*((機器台帳!$B$2:$B$400=$B19)+(機器台帳!$B$2:$B$400="両面")+($B19="両面")>0)*(機器台帳!$C$2:$C$400<=$C19+$D19-1)*(機器台帳!$C$2:$C$400+機器台帳!$D$2:$D$400-1>=$C19)*(機器台帳!$F$2:$F$400<>""))-1>0,NOT(SUMPRODUCT(--ISNUMBER(SEARCH({"棚板","棚","アングル","ｱﾝｸﾞﾙ","使用不可","ケーブル","ｹｰﾌﾞﾙ","PatchPnael","パッチ","引き出し","引出","ブランク","ﾌﾞﾗﾝｸ","マネージ","ﾏﾈｰｼﾞ","PDU","ONU"},$F19&"")))>0)),"／同じUに他の機器(横並びなら正常)","")&IF(AND(M19<>"",COUNTIFS(回路定義!$A:$A,A19,回路定義!$B:$B,M19)=0),"／回路1が定義にない","")&IF(AND(P19<>"",COUNTIFS(回路定義!$A:$A,A19,回路定義!$B:$B,P19)=0),"／回路2が定義にない","")&IF(AND(S19<>"",COUNTIFS(回路定義!$A:$A,A19,回路定義!$B:$B,S19)=0),"／回路3が定義にない",""),2,300)))
